Workbook

Sheet APR and payment
C3: BASIC INFORMATION | P3: Metoda půlení intervalů
C4: Loan amount | E4: 4000000 | F4: currency | L4: weekly | M4: 52 | P4: A | Q4: B | R4: půlka | S4: f(A) | T4: f(B) | U4: f(půlka)
C5: Number of payments | E5: 360 | L5: monthly | M5: 12 | O5: 1 | P5: 1e-10 | Q5: 10 | R5: =(P5+Q5)/2 -> 5 | S5: =$E$4-$E$10-$E$11*(1+P5)^(-$E$5/$L$9)-$E$13*(1+P5)^(-$H$13/$L$9)-$E$14*(1+P5)^(-$H$14/$L$9) +$E$24*((1-(1+P5)^(-$E$5/$L$9)))/(1-(1+P5)^(1/$L$9))+$E$17*((1-(1+P5)^(-$J$20/$M$4)))/(1-(1+P5)^(1/$M$4))+$E$18*((1-(1+P5)^(-$J$21/$M$5)))/(1-(1+P5)^(1/$M$5))+$E$19*((1-(1+P5)^(-$J$22/$M$6)))/(1-(1+P5)^(1/$M$6))+$E$20*((1-(1+P5)^(-$J$23/$M$7)))/(1-(1+P5)^(1/$M$7))+$E$21*((1-(1+P5)^(-$J$24/$M$8)))/(1-(1+P5)^(1/$M$8)) -> -4096543.4 | T5: =$E$4-$E$10-$E$11*(1+Q5)^(-$E$5/$L$9)-$E$13*(1+Q5)^(-$H$13/$L$9)-$E$14*(1+Q5)^(-$H$14/$L$9) +$E$24*((1-(1+Q5)^(-$E$5/$L$9)))/(1-(1+Q5)^(1/$L$9))+$E$17*((1-(1+Q5)^(-$J$20/$M$4)))/(1-(1+Q5)^(1/$M$4))+$E$18*((1-(1+Q5)^(-$J$21/$M$5)))/(1-(1+Q5)^(1/$M$5))+$E$19*((1-(1+Q5)^(-$J$22/$M$6)))/(1-(1+Q5)^(1/$M$6))+$E$20*((1-(1+Q5)^(-$J$23/$M$7)))/(1-(1+Q5)^(1/$M$7))+$E$21*((1-(1+Q5)^(-$J$24/$M$8)))/(1-(1+Q5)^(1/$M$8)) -> 3894207.3 | U5: =$E$4-$E$10-$E$11*(1+R5)^(-$E$5/$L$9)-$E$13*(1+R5)^(-$H$13/$L$9)-$E$14*(1+R5)^(-$H$14/$L$9) +$E$24*((1-(1+R5)^(-$E$5/$L$9)))/(1-(1+R5)^(1/$L$9))+$E$17*((1-(1+R5)^(-$J$20/$M$4)))/(1-(1+R5)^(1/$M$4))+$E$18*((1-(1+R5)^(-$J$21/$M$5)))/(1-(1+R5)^(1/$M$5))+$E$19*((1-(1+R5)^(-$J$22/$M$6)))/(1-(1+R5)^(1/$M$6))+$E$20*((1-(1+R5)^(-$J$23/$M$7)))/(1-(1+R5)^(1/$M$7))+$E$21*((1-(1+R5)^(-$J$24/$M$8)))/(1-(1+R5)^(1/$M$8)) -> 3856205.9
C6: Annual interest rate | E6: 0.054 | F6: p.a. | L6: quarterly | M6: 4 | O6: 2 | P6: =IF(S5*U5>=0,R5,P5) -> 1e-10 | Q6: =IF(T5*U5>=0,R5,Q5) -> 5 | R6: =(P6+Q6)/2 -> 2.5 | S6: =$E$4-$E$10-$E$11*(1+P6)^(-$E$5/$L$9)-$E$13*(1+P6)^(-$H$13/$L$9)-$E$14*(1+P6)^(-$H$14/$L$9) +$E$24*((1-(1+P6)^(-$E$5/$L$9)))/(1-(1+P6)^(1/$L$9))+$E$17*((1-(1+P6)^(-$J$20/$M$4)))/(1-(1+P6)^(1/$M$4))+$E$18*((1-(1+P6)^(-$J$21/$M$5)))/(1-(1+P6)^(1/$M$5))+$E$19*((1-(1+P6)^(-$J$22/$M$6)))/(1-(1+P6)^(1/$M$6))+$E$20*((1-(1+P6)^(-$J$23/$M$7)))/(1-(1+P6)^(1/$M$7))+$E$21*((1-(1+P6)^(-$J$24/$M$8)))/(1-(1+P6)^(1/$M$8)) -> -4096543.4 | T6: =$E$4-$E$10-$E$11*(1+Q6)^(-$E$5/$L$9)-$E$13*(1+Q6)^(-$H$13/$L$9)-$E$14*(1+Q6)^(-$H$14/$L$9) +$E$24*((1-(1+Q6)^(-$E$5/$L$9)))/(1-(1+Q6)^(1/$L$9))+$E$17*((1-(1+Q6)^(-$J$20/$M$4)))/(1-(1+Q6)^(1/$M$4))+$E$18*((1-(1+Q6)^(-$J$21/$M$5)))/(1-(1+Q6)^(1/$M$5))+$E$19*((1-(1+Q6)^(-$J$22/$M$6)))/(1-(1+Q6)^(1/$M$6))+$E$20*((1-(1+Q6)^(-$J$23/$M$7)))/(1-(1+Q6)^(1/$M$7))+$E$21*((1-(1+Q6)^(-$J$24/$M$8)))/(1-(1+Q6)^(1/$M$8)) -> 3856205.9 | U6: =$E$4-$E$10-$E$11*(1+R6)^(-$E$5/$L$9)-$E$13*(1+R6)^(-$H$13/$L$9)-$E$14*(1+R6)^(-$H$14/$L$9) +$E$24*((1-(1+R6)^(-$E$5/$L$9)))/(1-(1+R6)^(1/$L$9))+$E$17*((1-(1+R6)^(-$J$20/$M$4)))/(1-(1+R6)^(1/$M$4))+$E$18*((1-(1+R6)^(-$J$21/$M$5)))/(1-(1+R6)^(1/$M$5))+$E$19*((1-(1+R6)^(-$J$22/$M$6)))/(1-(1+R6)^(1/$M$6))+$E$20*((1-(1+R6)^(-$J$23/$M$7)))/(1-(1+R6)^(1/$M$7))+$E$21*((1-(1+R6)^(-$J$24/$M$8)))/(1-(1+R6)^(1/$M$8)) -> 3791473.7
C7: Payment frequency | E7: monthly | L7: semiannual | M7: 2 | O7: 3 | P7: =IF(S6*U6>=0,R6,P6) -> 1e-10 | Q7: =IF(T6*U6>=0,R6,Q6) -> 2.5 | R7: =(P7+Q7)/2 -> 1.25 | S7: =$E$4-$E$10-$E$11*(1+P7)^(-$E$5/$L$9)-$E$13*(1+P7)^(-$H$13/$L$9)-$E$14*(1+P7)^(-$H$14/$L$9) +$E$24*((1-(1+P7)^(-$E$5/$L$9)))/(1-(1+P7)^(1/$L$9))+$E$17*((1-(1+P7)^(-$J$20/$M$4)))/(1-(1+P7)^(1/$M$4))+$E$18*((1-(1+P7)^(-$J$21/$M$5)))/(1-(1+P7)^(1/$M$5))+$E$19*((1-(1+P7)^(-$J$22/$M$6)))/(1-(1+P7)^(1/$M$6))+$E$20*((1-(1+P7)^(-$J$23/$M$7)))/(1-(1+P7)^(1/$M$7))+$E$21*((1-(1+P7)^(-$J$24/$M$8)))/(1-(1+P7)^(1/$M$8)) -> -4096543.4 | T7: =$E$4-$E$10-$E$11*(1+Q7)^(-$E$5/$L$9)-$E$13*(1+Q7)^(-$H$13/$L$9)-$E$14*(1+Q7)^(-$H$14/$L$9) +$E$24*((1-(1+Q7)^(-$E$5/$L$9)))/(1-(1+Q7)^(1/$L$9))+$E$17*((1-(1+Q7)^(-$J$20/$M$4)))/(1-(1+Q7)^(1/$M$4))+$E$18*((1-(1+Q7)^(-$J$21/$M$5)))/(1-(1+Q7)^(1/$M$5))+$E$19*((1-(1+Q7)^(-$J$22/$M$6)))/(1-(1+Q7)^(1/$M$6))+$E$20*((1-(1+Q7)^(-$J$23/$M$7)))/(1-(1+Q7)^(1/$M$7))+$E$21*((1-(1+Q7)^(-$J$24/$M$8)))/(1-(1+Q7)^(1/$M$8)) -> 3791473.7 | U7: =$E$4-$E$10-$E$11*(1+R7)^(-$E$5/$L$9)-$E$13*(1+R7)^(-$H$13/$L$9)-$E$14*(1+R7)^(-$H$14/$L$9) +$E$24*((1-(1+R7)^(-$E$5/$L$9)))/(1-(1+R7)^(1/$L$9))+$E$17*((1-(1+R7)^(-$J$20/$M$4)))/(1-(1+R7)^(1/$M$4))+$E$18*((1-(1+R7)^(-$J$21/$M$5)))/(1-(1+R7)^(1/$M$5))+$E$19*((1-(1+R7)^(-$J$22/$M$6)))/(1-(1+R7)^(1/$M$6))+$E$20*((1-(1+R7)^(-$J$23/$M$7)))/(1-(1+R7)^(1/$M$7))+$E$21*((1-(1+R7)^(-$J$24/$M$8)))/(1-(1+R7)^(1/$M$8)) -> 3674185.3
L8: annual | M8: 1 | O8: 4 | P8: =IF(S7*U7>=0,R7,P7) -> 1e-10 | Q8: =IF(T7*U7>=0,R7,Q7) -> 1.25 | R8: =(P8+Q8)/2 -> 0.625 | S8: =$E$4-$E$10-$E$11*(1+P8)^(-$E$5/$L$9)-$E$13*(1+P8)^(-$H$13/$L$9)-$E$14*(1+P8)^(-$H$14/$L$9) +$E$24*((1-(1+P8)^(-$E$5/$L$9)))/(1-(1+P8)^(1/$L$9))+$E$17*((1-(1+P8)^(-$J$20/$M$4)))/(1-(1+P8)^(1/$M$4))+$E$18*((1-(1+P8)^(-$J$21/$M$5)))/(1-(1+P8)^(1/$M$5))+$E$19*((1-(1+P8)^(-$J$22/$M$6)))/(1-(1+P8)^(1/$M$6))+$E$20*((1-(1+P8)^(-$J$23/$M$7)))/(1-(1+P8)^(1/$M$7))+$E$21*((1-(1+P8)^(-$J$24/$M$8)))/(1-(1+P8)^(1/$M$8)) -> -4096543.4 | T8: =$E$4-$E$10-$E$11*(1+Q8)^(-$E$5/$L$9)-$E$13*(1+Q8)^(-$H$13/$L$9)-$E$14*(1+Q8)^(-$H$14/$L$9) +$E$24*((1-(1+Q8)^(-$E$5/$L$9)))/(1-(1+Q8)^(1/$L$9))+$E$17*((1-(1+Q8)^(-$J$20/$M$4)))/(1-(1+Q8)^(1/$M$4))+$E$18*((1-(1+Q8)^(-$J$21/$M$5)))/(1-(1+Q8)^(1/$M$5))+$E$19*((1-(1+Q8)^(-$J$22/$M$6)))/(1-(1+Q8)^(1/$M$6))+$E$20*((1-(1+Q8)^(-$J$23/$M$7)))/(1-(1+Q8)^(1/$M$7))+$E$21*((1-(1+Q8)^(-$J$24/$M$8)))/(1-(1+Q8)^(1/$M$8)) -> 3674185.3 | U8: =$E$4-$E$10-$E$11*(1+R8)^(-$E$5/$L$9)-$E$13*(1+R8)^(-$H$13/$L$9)-$E$14*(1+R8)^(-$H$14/$L$9) +$E$24*((1-(1+R8)^(-$E$5/$L$9)))/(1-(1+R8)^(1/$L$9))+$E$17*((1-(1+R8)^(-$J$20/$M$4)))/(1-(1+R8)^(1/$M$4))+$E$18*((1-(1+R8)^(-$J$21/$M$5)))/(1-(1+R8)^(1/$M$5))+$E$19*((1-(1+R8)^(-$J$22/$M$6)))/(1-(1+R8)^(1/$M$6))+$E$20*((1-(1+R8)^(-$J$23/$M$7)))/(1-(1+R8)^(1/$M$7))+$E$21*((1-(1+R8)^(-$J$24/$M$8)))/(1-(1+R8)^(1/$M$8)) -> 3451249.3
C9: ONE TIME FEES | L9: =IF(E7=L4,M4,IF(E7=L5,M5,IF(E7=L6,M6,IF(E7=L7,M7,IF(E7=L8,M8))))) -> 12 | O9: 5 | P9: =IF(S8*U8>=0,R8,P8) -> 1e-10 | Q9: =IF(T8*U8>=0,R8,Q8) -> 0.625 | R9: =(P9+Q9)/2 -> 0.3125 | S9: =$E$4-$E$10-$E$11*(1+P9)^(-$E$5/$L$9)-$E$13*(1+P9)^(-$H$13/$L$9)-$E$14*(1+P9)^(-$H$14/$L$9) +$E$24*((1-(1+P9)^(-$E$5/$L$9)))/(1-(1+P9)^(1/$L$9))+$E$17*((1-(1+P9)^(-$J$20/$M$4)))/(1-(1+P9)^(1/$M$4))+$E$18*((1-(1+P9)^(-$J$21/$M$5)))/(1-(1+P9)^(1/$M$5))+$E$19*((1-(1+P9)^(-$J$22/$M$6)))/(1-(1+P9)^(1/$M$6))+$E$20*((1-(1+P9)^(-$J$23/$M$7)))/(1-(1+P9)^(1/$M$7))+$E$21*((1-(1+P9)^(-$J$24/$M$8)))/(1-(1+P9)^(1/$M$8)) -> -4096543.4 | T9: =$E$4-$E$10-$E$11*(1+Q9)^(-$E$5/$L$9)-$E$13*(1+Q9)^(-$H$13/$L$9)-$E$14*(1+Q9)^(-$H$14/$L$9) +$E$24*((1-(1+Q9)^(-$E$5/$L$9)))/(1-(1+Q9)^(1/$L$9))+$E$17*((1-(1+Q9)^(-$J$20/$M$4)))/(1-(1+Q9)^(1/$M$4))+$E$18*((1-(1+Q9)^(-$J$21/$M$5)))/(1-(1+Q9)^(1/$M$5))+$E$19*((1-(1+Q9)^(-$J$22/$M$6)))/(1-(1+Q9)^(1/$M$6))+$E$20*((1-(1+Q9)^(-$J$23/$M$7)))/(1-(1+Q9)^(1/$M$7))+$E$21*((1-(1+Q9)^(-$J$24/$M$8)))/(1-(1+Q9)^(1/$M$8)) -> 3451249.3 | U9: =$E$4-$E$10-$E$11*(1+R9)^(-$E$5/$L$9)-$E$13*(1+R9)^(-$H$13/$L$9)-$E$14*(1+R9)^(-$H$14/$L$9) +$E$24*((1-(1+R9)^(-$E$5/$L$9)))/(1-(1+R9)^(1/$L$9))+$E$17*((1-(1+R9)^(-$J$20/$M$4)))/(1-(1+R9)^(1/$M$4))+$E$18*((1-(1+R9)^(-$J$21/$M$5)))/(1-(1+R9)^(1/$M$5))+$E$19*((1-(1+R9)^(-$J$22/$M$6)))/(1-(1+R9)^(1/$M$6))+$E$20*((1-(1+R9)^(-$J$23/$M$7)))/(1-(1+R9)^(1/$M$7))+$E$21*((1-(1+R9)^(-$J$24/$M$8)))/(1-(1+R9)^(1/$M$8)) -> 3015194.2
C10: signing fee | E10: 4000 | F10: currency | K10: i/p | L10: =E6/L9 -> 0.0045 | O10: 6 | P10: =IF(S9*U9>=0,R9,P9) -> 1e-10 | Q10: =IF(T9*U9>=0,R9,Q9) -> 0.3125 | R10: =(P10+Q10)/2 -> 0.15625 | S10: =$E$4-$E$10-$E$11*(1+P10)^(-$E$5/$L$9)-$E$13*(1+P10)^(-$H$13/$L$9)-$E$14*(1+P10)^(-$H$14/$L$9) +$E$24*((1-(1+P10)^(-$E$5/$L$9)))/(1-(1+P10)^(1/$L$9))+$E$17*((1-(1+P10)^(-$J$20/$M$4)))/(1-(1+P10)^(1/$M$4))+$E$18*((1-(1+P10)^(-$J$21/$M$5)))/(1-(1+P10)^(1/$M$5))+$E$19*((1-(1+P10)^(-$J$22/$M$6)))/(1-(1+P10)^(1/$M$6))+$E$20*((1-(1+P10)^(-$J$23/$M$7)))/(1-(1+P10)^(1/$M$7))+$E$21*((1-(1+P10)^(-$J$24/$M$8)))/(1-(1+P10)^(1/$M$8)) -> -4096543.4 | T10: =$E$4-$E$10-$E$11*(1+Q10)^(-$E$5/$L$9)-$E$13*(1+Q10)^(-$H$13/$L$9)-$E$14*(1+Q10)^(-$H$14/$L$9) +$E$24*((1-(1+Q10)^(-$E$5/$L$9)))/(1-(1+Q10)^(1/$L$9))+$E$17*((1-(1+Q10)^(-$J$20/$M$4)))/(1-(1+Q10)^(1/$M$4))+$E$18*((1-(1+Q10)^(-$J$21/$M$5)))/(1-(1+Q10)^(1/$M$5))+$E$19*((1-(1+Q10)^(-$J$22/$M$6)))/(1-(1+Q10)^(1/$M$6))+$E$20*((1-(1+Q10)^(-$J$23/$M$7)))/(1-(1+Q10)^(1/$M$7))+$E$21*((1-(1+Q10)^(-$J$24/$M$8)))/(1-(1+Q10)^(1/$M$8)) -> 3015194.2 | U10: =$E$4-$E$10-$E$11*(1+R10)^(-$E$5/$L$9)-$E$13*(1+R10)^(-$H$13/$L$9)-$E$14*(1+R10)^(-$H$14/$L$9) +$E$24*((1-(1+R10)^(-$E$5/$L$9)))/(1-(1+R10)^(1/$L$9))+$E$17*((1-(1+R10)^(-$J$20/$M$4)))/(1-(1+R10)^(1/$M$4))+$E$18*((1-(1+R10)^(-$J$21/$M$5)))/(1-(1+R10)^(1/$M$5))+$E$19*((1-(1+R10)^(-$J$22/$M$6)))/(1-(1+R10)^(1/$M$6))+$E$20*((1-(1+R10)^(-$J$23/$M$7)))/(1-(1+R10)^(1/$M$7))+$E$21*((1-(1+R10)^(-$J$24/$M$8)))/(1-(1+R10)^(1/$M$8)) -> 2172625.4
C11: termination fee | E11: 0 | F11: currency | O11: 7 | P11: =IF(S10*U10>=0,R10,P10) -> 1e-10 | Q11: =IF(T10*U10>=0,R10,Q10) -> 0.15625 | R11: =(P11+Q11)/2 -> 0.078125 | S11: =$E$4-$E$10-$E$11*(1+P11)^(-$E$5/$L$9)-$E$13*(1+P11)^(-$H$13/$L$9)-$E$14*(1+P11)^(-$H$14/$L$9) +$E$24*((1-(1+P11)^(-$E$5/$L$9)))/(1-(1+P11)^(1/$L$9))+$E$17*((1-(1+P11)^(-$J$20/$M$4)))/(1-(1+P11)^(1/$M$4))+$E$18*((1-(1+P11)^(-$J$21/$M$5)))/(1-(1+P11)^(1/$M$5))+$E$19*((1-(1+P11)^(-$J$22/$M$6)))/(1-(1+P11)^(1/$M$6))+$E$20*((1-(1+P11)^(-$J$23/$M$7)))/(1-(1+P11)^(1/$M$7))+$E$21*((1-(1+P11)^(-$J$24/$M$8)))/(1-(1+P11)^(1/$M$8)) -> -4096543.4 | T11: =$E$4-$E$10-$E$11*(1+Q11)^(-$E$5/$L$9)-$E$13*(1+Q11)^(-$H$13/$L$9)-$E$14*(1+Q11)^(-$H$14/$L$9) +$E$24*((1-(1+Q11)^(-$E$5/$L$9)))/(1-(1+Q11)^(1/$L$9))+$E$17*((1-(1+Q11)^(-$J$20/$M$4)))/(1-(1+Q11)^(1/$M$4))+$E$18*((1-(1+Q11)^(-$J$21/$M$5)))/(1-(1+Q11)^(1/$M$5))+$E$19*((1-(1+Q11)^(-$J$22/$M$6)))/(1-(1+Q11)^(1/$M$6))+$E$20*((1-(1+Q11)^(-$J$23/$M$7)))/(1-(1+Q11)^(1/$M$7))+$E$21*((1-(1+Q11)^(-$J$24/$M$8)))/(1-(1+Q11)^(1/$M$8)) -> 2172625.4 | U11: =$E$4-$E$10-$E$11*(1+R11)^(-$E$5/$L$9)-$E$13*(1+R11)^(-$H$13/$L$9)-$E$14*(1+R11)^(-$H$14/$L$9) +$E$24*((1-(1+R11)^(-$E$5/$L$9)))/(1-(1+R11)^(1/$L$9))+$E$17*((1-(1+R11)^(-$J$20/$M$4)))/(1-(1+R11)^(1/$M$4))+$E$18*((1-(1+R11)^(-$J$21/$M$5)))/(1-(1+R11)^(1/$M$5))+$E$19*((1-(1+R11)^(-$J$22/$M$6)))/(1-(1+R11)^(1/$M$6))+$E$20*((1-(1+R11)^(-$J$23/$M$7)))/(1-(1+R11)^(1/$M$7))+$E$21*((1-(1+R11)^(-$J$24/$M$8)))/(1-(1+R11)^(1/$M$8)) -> 795277.16
C12: SPECIAL FEE | O12: 8 | P12: =IF(S11*U11>=0,R11,P11) -> 1e-10 | Q12: =IF(T11*U11>=0,R11,Q11) -> 0.078125 | R12: =(P12+Q12)/2 -> 0.0390625 | S12: =$E$4-$E$10-$E$11*(1+P12)^(-$E$5/$L$9)-$E$13*(1+P12)^(-$H$13/$L$9)-$E$14*(1+P12)^(-$H$14/$L$9) +$E$24*((1-(1+P12)^(-$E$5/$L$9)))/(1-(1+P12)^(1/$L$9))+$E$17*((1-(1+P12)^(-$J$20/$M$4)))/(1-(1+P12)^(1/$M$4))+$E$18*((1-(1+P12)^(-$J$21/$M$5)))/(1-(1+P12)^(1/$M$5))+$E$19*((1-(1+P12)^(-$J$22/$M$6)))/(1-(1+P12)^(1/$M$6))+$E$20*((1-(1+P12)^(-$J$23/$M$7)))/(1-(1+P12)^(1/$M$7))+$E$21*((1-(1+P12)^(-$J$24/$M$8)))/(1-(1+P12)^(1/$M$8)) -> -4096543.4 | T12: =$E$4-$E$10-$E$11*(1+Q12)^(-$E$5/$L$9)-$E$13*(1+Q12)^(-$H$13/$L$9)-$E$14*(1+Q12)^(-$H$14/$L$9) +$E$24*((1-(1+Q12)^(-$E$5/$L$9)))/(1-(1+Q12)^(1/$L$9))+$E$17*((1-(1+Q12)^(-$J$20/$M$4)))/(1-(1+Q12)^(1/$M$4))+$E$18*((1-(1+Q12)^(-$J$21/$M$5)))/(1-(1+Q12)^(1/$M$5))+$E$19*((1-(1+Q12)^(-$J$22/$M$6)))/(1-(1+Q12)^(1/$M$6))+$E$20*((1-(1+Q12)^(-$J$23/$M$7)))/(1-(1+Q12)^(1/$M$7))+$E$21*((1-(1+Q12)^(-$J$24/$M$8)))/(1-(1+Q12)^(1/$M$8)) -> 795277.16 | U12: =$E$4-$E$10-$E$11*(1+R12)^(-$E$5/$L$9)-$E$13*(1+R12)^(-$H$13/$L$9)-$E$14*(1+R12)^(-$H$14/$L$9) +$E$24*((1-(1+R12)^(-$E$5/$L$9)))/(1-(1+R12)^(1/$L$9))+$E$17*((1-(1+R12)^(-$J$20/$M$4)))/(1-(1+R12)^(1/$M$4))+$E$18*((1-(1+R12)^(-$J$21/$M$5)))/(1-(1+R12)^(1/$M$5))+$E$19*((1-(1+R12)^(-$J$22/$M$6)))/(1-(1+R12)^(1/$M$6))+$E$20*((1-(1+R12)^(-$J$23/$M$7)))/(1-(1+R12)^(1/$M$7))+$E$21*((1-(1+R12)^(-$J$24/$M$8)))/(1-(1+R12)^(1/$M$8)) -> -806130.8
C13: fee during the loan term | E13: 500 | F13: currency | G13: paid at the time | H13: 4 | O13: 9 | P13: =IF(S12*U12>=0,R12,P12) -> 0.0390625 | Q13: =IF(T12*U12>=0,R12,Q12) -> 0.078125 | R13: =(P13+Q13)/2 -> 0.05859375 | S13: =$E$4-$E$10-$E$11*(1+P13)^(-$E$5/$L$9)-$E$13*(1+P13)^(-$H$13/$L$9)-$E$14*(1+P13)^(-$H$14/$L$9) +$E$24*((1-(1+P13)^(-$E$5/$L$9)))/(1-(1+P13)^(1/$L$9))+$E$17*((1-(1+P13)^(-$J$20/$M$4)))/(1-(1+P13)^(1/$M$4))+$E$18*((1-(1+P13)^(-$J$21/$M$5)))/(1-(1+P13)^(1/$M$5))+$E$19*((1-(1+P13)^(-$J$22/$M$6)))/(1-(1+P13)^(1/$M$6))+$E$20*((1-(1+P13)^(-$J$23/$M$7)))/(1-(1+P13)^(1/$M$7))+$E$21*((1-(1+P13)^(-$J$24/$M$8)))/(1-(1+P13)^(1/$M$8)) -> -806130.8 | T13: =$E$4-$E$10-$E$11*(1+Q13)^(-$E$5/$L$9)-$E$13*(1+Q13)^(-$H$13/$L$9)-$E$14*(1+Q13)^(-$H$14/$L$9) +$E$24*((1-(1+Q13)^(-$E$5/$L$9)))/(1-(1+Q13)^(1/$L$9))+$E$17*((1-(1+Q13)^(-$J$20/$M$4)))/(1-(1+Q13)^(1/$M$4))+$E$18*((1-(1+Q13)^(-$J$21/$M$5)))/(1-(1+Q13)^(1/$M$5))+$E$19*((1-(1+Q13)^(-$J$22/$M$6)))/(1-(1+Q13)^(1/$M$6))+$E$20*((1-(1+Q13)^(-$J$23/$M$7)))/(1-(1+Q13)^(1/$M$7))+$E$21*((1-(1+Q13)^(-$J$24/$M$8)))/(1-(1+Q13)^(1/$M$8)) -> 795277.16 | U13: =$E$4-$E$10-$E$11*(1+R13)^(-$E$5/$L$9)-$E$13*(1+R13)^(-$H$13/$L$9)-$E$14*(1+R13)^(-$H$14/$L$9) +$E$24*((1-(1+R13)^(-$E$5/$L$9)))/(1-(1+R13)^(1/$L$9))+$E$17*((1-(1+R13)^(-$J$20/$M$4)))/(1-(1+R13)^(1/$M$4))+$E$18*((1-(1+R13)^(-$J$21/$M$5)))/(1-(1+R13)^(1/$M$5))+$E$19*((1-(1+R13)^(-$J$22/$M$6)))/(1-(1+R13)^(1/$M$6))+$E$20*((1-(1+R13)^(-$J$23/$M$7)))/(1-(1+R13)^(1/$M$7))+$E$21*((1-(1+R13)^(-$J$24/$M$8)))/(1-(1+R13)^(1/$M$8)) -> 125998.38
C14: fee during the loan term | E14: 0 | F14: currency | G14: paid at the time | H14: 0 | O14: 10 | P14: =IF(S13*U13>=0,R13,P13) -> 0.0390625 | Q14: =IF(T13*U13>=0,R13,Q13) -> 0.05859375 | R14: =(P14+Q14)/2 -> 0.048828125 | S14: =$E$4-$E$10-$E$11*(1+P14)^(-$E$5/$L$9)-$E$13*(1+P14)^(-$H$13/$L$9)-$E$14*(1+P14)^(-$H$14/$L$9) +$E$24*((1-(1+P14)^(-$E$5/$L$9)))/(1-(1+P14)^(1/$L$9))+$E$17*((1-(1+P14)^(-$J$20/$M$4)))/(1-(1+P14)^(1/$M$4))+$E$18*((1-(1+P14)^(-$J$21/$M$5)))/(1-(1+P14)^(1/$M$5))+$E$19*((1-(1+P14)^(-$J$22/$M$6)))/(1-(1+P14)^(1/$M$6))+$E$20*((1-(1+P14)^(-$J$23/$M$7)))/(1-(1+P14)^(1/$M$7))+$E$21*((1-(1+P14)^(-$J$24/$M$8)))/(1-(1+P14)^(1/$M$8)) -> -806130.8 | T14: =$E$4-$E$10-$E$11*(1+Q14)^(-$E$5/$L$9)-$E$13*(1+Q14)^(-$H$13/$L$9)-$E$14*(1+Q14)^(-$H$14/$L$9) +$E$24*((1-(1+Q14)^(-$E$5/$L$9)))/(1-(1+Q14)^(1/$L$9))+$E$17*((1-(1+Q14)^(-$J$20/$M$4)))/(1-(1+Q14)^(1/$M$4))+$E$18*((1-(1+Q14)^(-$J$21/$M$5)))/(1-(1+Q14)^(1/$M$5))+$E$19*((1-(1+Q14)^(-$J$22/$M$6)))/(1-(1+Q14)^(1/$M$6))+$E$20*((1-(1+Q14)^(-$J$23/$M$7)))/(1-(1+Q14)^(1/$M$7))+$E$21*((1-(1+Q14)^(-$J$24/$M$8)))/(1-(1+Q14)^(1/$M$8)) -> 125998.38 | U14: =$E$4-$E$10-$E$11*(1+R14)^(-$E$5/$L$9)-$E$13*(1+R14)^(-$H$13/$L$9)-$E$14*(1+R14)^(-$H$14/$L$9) +$E$24*((1-(1+R14)^(-$E$5/$L$9)))/(1-(1+R14)^(1/$L$9))+$E$17*((1-(1+R14)^(-$J$20/$M$4)))/(1-(1+R14)^(1/$M$4))+$E$18*((1-(1+R14)^(-$J$21/$M$5)))/(1-(1+R14)^(1/$M$5))+$E$19*((1-(1+R14)^(-$J$22/$M$6)))/(1-(1+R14)^(1/$M$6))+$E$20*((1-(1+R14)^(-$J$23/$M$7)))/(1-(1+R14)^(1/$M$7))+$E$21*((1-(1+R14)^(-$J$24/$M$8)))/(1-(1+R14)^(1/$M$8)) -> -300117.85
O15: 11 | P15: =IF(S14*U14>=0,R14,P14) -> 0.048828125 | Q15: =IF(T14*U14>=0,R14,Q14) -> 0.05859375 | R15: =(P15+Q15)/2 -> 0.053710938 | S15: =$E$4-$E$10-$E$11*(1+P15)^(-$E$5/$L$9)-$E$13*(1+P15)^(-$H$13/$L$9)-$E$14*(1+P15)^(-$H$14/$L$9) +$E$24*((1-(1+P15)^(-$E$5/$L$9)))/(1-(1+P15)^(1/$L$9))+$E$17*((1-(1+P15)^(-$J$20/$M$4)))/(1-(1+P15)^(1/$M$4))+$E$18*((1-(1+P15)^(-$J$21/$M$5)))/(1-(1+P15)^(1/$M$5))+$E$19*((1-(1+P15)^(-$J$22/$M$6)))/(1-(1+P15)^(1/$M$6))+$E$20*((1-(1+P15)^(-$J$23/$M$7)))/(1-(1+P15)^(1/$M$7))+$E$21*((1-(1+P15)^(-$J$24/$M$8)))/(1-(1+P15)^(1/$M$8)) -> -300117.85 | T15: =$E$4-$E$10-$E$11*(1+Q15)^(-$E$5/$L$9)-$E$13*(1+Q15)^(-$H$13/$L$9)-$E$14*(1+Q15)^(-$H$14/$L$9) +$E$24*((1-(1+Q15)^(-$E$5/$L$9)))/(1-(1+Q15)^(1/$L$9))+$E$17*((1-(1+Q15)^(-$J$20/$M$4)))/(1-(1+Q15)^(1/$M$4))+$E$18*((1-(1+Q15)^(-$J$21/$M$5)))/(1-(1+Q15)^(1/$M$5))+$E$19*((1-(1+Q15)^(-$J$22/$M$6)))/(1-(1+Q15)^(1/$M$6))+$E$20*((1-(1+Q15)^(-$J$23/$M$7)))/(1-(1+Q15)^(1/$M$7))+$E$21*((1-(1+Q15)^(-$J$24/$M$8)))/(1-(1+Q15)^(1/$M$8)) -> 125998.38 | U15: =$E$4-$E$10-$E$11*(1+R15)^(-$E$5/$L$9)-$E$13*(1+R15)^(-$H$13/$L$9)-$E$14*(1+R15)^(-$H$14/$L$9) +$E$24*((1-(1+R15)^(-$E$5/$L$9)))/(1-(1+R15)^(1/$L$9))+$E$17*((1-(1+R15)^(-$J$20/$M$4)))/(1-(1+R15)^(1/$M$4))+$E$18*((1-(1+R15)^(-$J$21/$M$5)))/(1-(1+R15)^(1/$M$5))+$E$19*((1-(1+R15)^(-$J$22/$M$6)))/(1-(1+R15)^(1/$M$6))+$E$20*((1-(1+R15)^(-$J$23/$M$7)))/(1-(1+R15)^(1/$M$7))+$E$21*((1-(1+R15)^(-$J$24/$M$8)))/(1-(1+R15)^(1/$M$8)) -> -78089.717
C16: RECURRING FEES | O16: 12 | P16: =IF(S15*U15>=0,R15,P15) -> 0.053710938 | Q16: =IF(T15*U15>=0,R15,Q15) -> 0.05859375 | R16: =(P16+Q16)/2 -> 0.056152344 | S16: =$E$4-$E$10-$E$11*(1+P16)^(-$E$5/$L$9)-$E$13*(1+P16)^(-$H$13/$L$9)-$E$14*(1+P16)^(-$H$14/$L$9) +$E$24*((1-(1+P16)^(-$E$5/$L$9)))/(1-(1+P16)^(1/$L$9))+$E$17*((1-(1+P16)^(-$J$20/$M$4)))/(1-(1+P16)^(1/$M$4))+$E$18*((1-(1+P16)^(-$J$21/$M$5)))/(1-(1+P16)^(1/$M$5))+$E$19*((1-(1+P16)^(-$J$22/$M$6)))/(1-(1+P16)^(1/$M$6))+$E$20*((1-(1+P16)^(-$J$23/$M$7)))/(1-(1+P16)^(1/$M$7))+$E$21*((1-(1+P16)^(-$J$24/$M$8)))/(1-(1+P16)^(1/$M$8)) -> -78089.717 | T16: =$E$4-$E$10-$E$11*(1+Q16)^(-$E$5/$L$9)-$E$13*(1+Q16)^(-$H$13/$L$9)-$E$14*(1+Q16)^(-$H$14/$L$9) +$E$24*((1-(1+Q16)^(-$E$5/$L$9)))/(1-(1+Q16)^(1/$L$9))+$E$17*((1-(1+Q16)^(-$J$20/$M$4)))/(1-(1+Q16)^(1/$M$4))+$E$18*((1-(1+Q16)^(-$J$21/$M$5)))/(1-(1+Q16)^(1/$M$5))+$E$19*((1-(1+Q16)^(-$J$22/$M$6)))/(1-(1+Q16)^(1/$M$6))+$E$20*((1-(1+Q16)^(-$J$23/$M$7)))/(1-(1+Q16)^(1/$M$7))+$E$21*((1-(1+Q16)^(-$J$24/$M$8)))/(1-(1+Q16)^(1/$M$8)) -> 125998.38 | U16: =$E$4-$E$10-$E$11*(1+R16)^(-$E$5/$L$9)-$E$13*(1+R16)^(-$H$13/$L$9)-$E$14*(1+R16)^(-$H$14/$L$9) +$E$24*((1-(1+R16)^(-$E$5/$L$9)))/(1-(1+R16)^(1/$L$9))+$E$17*((1-(1+R16)^(-$J$20/$M$4)))/(1-(1+R16)^(1/$M$4))+$E$18*((1-(1+R16)^(-$J$21/$M$5)))/(1-(1+R16)^(1/$M$5))+$E$19*((1-(1+R16)^(-$J$22/$M$6)))/(1-(1+R16)^(1/$M$6))+$E$20*((1-(1+R16)^(-$J$23/$M$7)))/(1-(1+R16)^(1/$M$7))+$E$21*((1-(1+R16)^(-$J$24/$M$8)))/(1-(1+R16)^(1/$M$8)) -> 26082.432
C17: =L4 -> weekly | E17: 0 | F17: currency | O17: 13 | P17: =IF(S16*U16>=0,R16,P16) -> 0.053710938 | Q17: =IF(T16*U16>=0,R16,Q16) -> 0.056152344 | R17: =(P17+Q17)/2 -> 0.054931641 | S17: =$E$4-$E$10-$E$11*(1+P17)^(-$E$5/$L$9)-$E$13*(1+P17)^(-$H$13/$L$9)-$E$14*(1+P17)^(-$H$14/$L$9) +$E$24*((1-(1+P17)^(-$E$5/$L$9)))/(1-(1+P17)^(1/$L$9))+$E$17*((1-(1+P17)^(-$J$20/$M$4)))/(1-(1+P17)^(1/$M$4))+$E$18*((1-(1+P17)^(-$J$21/$M$5)))/(1-(1+P17)^(1/$M$5))+$E$19*((1-(1+P17)^(-$J$22/$M$6)))/(1-(1+P17)^(1/$M$6))+$E$20*((1-(1+P17)^(-$J$23/$M$7)))/(1-(1+P17)^(1/$M$7))+$E$21*((1-(1+P17)^(-$J$24/$M$8)))/(1-(1+P17)^(1/$M$8)) -> -78089.717 | T17: =$E$4-$E$10-$E$11*(1+Q17)^(-$E$5/$L$9)-$E$13*(1+Q17)^(-$H$13/$L$9)-$E$14*(1+Q17)^(-$H$14/$L$9) +$E$24*((1-(1+Q17)^(-$E$5/$L$9)))/(1-(1+Q17)^(1/$L$9))+$E$17*((1-(1+Q17)^(-$J$20/$M$4)))/(1-(1+Q17)^(1/$M$4))+$E$18*((1-(1+Q17)^(-$J$21/$M$5)))/(1-(1+Q17)^(1/$M$5))+$E$19*((1-(1+Q17)^(-$J$22/$M$6)))/(1-(1+Q17)^(1/$M$6))+$E$20*((1-(1+Q17)^(-$J$23/$M$7)))/(1-(1+Q17)^(1/$M$7))+$E$21*((1-(1+Q17)^(-$J$24/$M$8)))/(1-(1+Q17)^(1/$M$8)) -> 26082.432 | U17: =$E$4-$E$10-$E$11*(1+R17)^(-$E$5/$L$9)-$E$13*(1+R17)^(-$H$13/$L$9)-$E$14*(1+R17)^(-$H$14/$L$9) +$E$24*((1-(1+R17)^(-$E$5/$L$9)))/(1-(1+R17)^(1/$L$9))+$E$17*((1-(1+R17)^(-$J$20/$M$4)))/(1-(1+R17)^(1/$M$4))+$E$18*((1-(1+R17)^(-$J$21/$M$5)))/(1-(1+R17)^(1/$M$5))+$E$19*((1-(1+R17)^(-$J$22/$M$6)))/(1-(1+R17)^(1/$M$6))+$E$20*((1-(1+R17)^(-$J$23/$M$7)))/(1-(1+R17)^(1/$M$7))+$E$21*((1-(1+R17)^(-$J$24/$M$8)))/(1-(1+R17)^(1/$M$8)) -> -25457.838
C18: =L5 -> monthly | E18: 0 | F18: currency | O18: 14 | P18: =IF(S17*U17>=0,R17,P17) -> 0.054931641 | Q18: =IF(T17*U17>=0,R17,Q17) -> 0.056152344 | R18: =(P18+Q18)/2 -> 0.055541992 | S18: =$E$4-$E$10-$E$11*(1+P18)^(-$E$5/$L$9)-$E$13*(1+P18)^(-$H$13/$L$9)-$E$14*(1+P18)^(-$H$14/$L$9) +$E$24*((1-(1+P18)^(-$E$5/$L$9)))/(1-(1+P18)^(1/$L$9))+$E$17*((1-(1+P18)^(-$J$20/$M$4)))/(1-(1+P18)^(1/$M$4))+$E$18*((1-(1+P18)^(-$J$21/$M$5)))/(1-(1+P18)^(1/$M$5))+$E$19*((1-(1+P18)^(-$J$22/$M$6)))/(1-(1+P18)^(1/$M$6))+$E$20*((1-(1+P18)^(-$J$23/$M$7)))/(1-(1+P18)^(1/$M$7))+$E$21*((1-(1+P18)^(-$J$24/$M$8)))/(1-(1+P18)^(1/$M$8)) -> -25457.838 | T18: =$E$4-$E$10-$E$11*(1+Q18)^(-$E$5/$L$9)-$E$13*(1+Q18)^(-$H$13/$L$9)-$E$14*(1+Q18)^(-$H$14/$L$9) +$E$24*((1-(1+Q18)^(-$E$5/$L$9)))/(1-(1+Q18)^(1/$L$9))+$E$17*((1-(1+Q18)^(-$J$20/$M$4)))/(1-(1+Q18)^(1/$M$4))+$E$18*((1-(1+Q18)^(-$J$21/$M$5)))/(1-(1+Q18)^(1/$M$5))+$E$19*((1-(1+Q18)^(-$J$22/$M$6)))/(1-(1+Q18)^(1/$M$6))+$E$20*((1-(1+Q18)^(-$J$23/$M$7)))/(1-(1+Q18)^(1/$M$7))+$E$21*((1-(1+Q18)^(-$J$24/$M$8)))/(1-(1+Q18)^(1/$M$8)) -> 26082.432 | U18: =$E$4-$E$10-$E$11*(1+R18)^(-$E$5/$L$9)-$E$13*(1+R18)^(-$H$13/$L$9)-$E$14*(1+R18)^(-$H$14/$L$9) +$E$24*((1-(1+R18)^(-$E$5/$L$9)))/(1-(1+R18)^(1/$L$9))+$E$17*((1-(1+R18)^(-$J$20/$M$4)))/(1-(1+R18)^(1/$M$4))+$E$18*((1-(1+R18)^(-$J$21/$M$5)))/(1-(1+R18)^(1/$M$5))+$E$19*((1-(1+R18)^(-$J$22/$M$6)))/(1-(1+R18)^(1/$M$6))+$E$20*((1-(1+R18)^(-$J$23/$M$7)))/(1-(1+R18)^(1/$M$7))+$E$21*((1-(1+R18)^(-$J$24/$M$8)))/(1-(1+R18)^(1/$M$8)) -> 446.99397
C19: =L6 -> quarterly | E19: 0 | F19: currency | J19: počet všech period | O19: 15 | P19: =IF(S18*U18>=0,R18,P18) -> 0.054931641 | Q19: =IF(T18*U18>=0,R18,Q18) -> 0.055541992 | R19: =(P19+Q19)/2 -> 0.055236817 | S19: =$E$4-$E$10-$E$11*(1+P19)^(-$E$5/$L$9)-$E$13*(1+P19)^(-$H$13/$L$9)-$E$14*(1+P19)^(-$H$14/$L$9) +$E$24*((1-(1+P19)^(-$E$5/$L$9)))/(1-(1+P19)^(1/$L$9))+$E$17*((1-(1+P19)^(-$J$20/$M$4)))/(1-(1+P19)^(1/$M$4))+$E$18*((1-(1+P19)^(-$J$21/$M$5)))/(1-(1+P19)^(1/$M$5))+$E$19*((1-(1+P19)^(-$J$22/$M$6)))/(1-(1+P19)^(1/$M$6))+$E$20*((1-(1+P19)^(-$J$23/$M$7)))/(1-(1+P19)^(1/$M$7))+$E$21*((1-(1+P19)^(-$J$24/$M$8)))/(1-(1+P19)^(1/$M$8)) -> -25457.838 | T19: =$E$4-$E$10-$E$11*(1+Q19)^(-$E$5/$L$9)-$E$13*(1+Q19)^(-$H$13/$L$9)-$E$14*(1+Q19)^(-$H$14/$L$9) +$E$24*((1-(1+Q19)^(-$E$5/$L$9)))/(1-(1+Q19)^(1/$L$9))+$E$17*((1-(1+Q19)^(-$J$20/$M$4)))/(1-(1+Q19)^(1/$M$4))+$E$18*((1-(1+Q19)^(-$J$21/$M$5)))/(1-(1+Q19)^(1/$M$5))+$E$19*((1-(1+Q19)^(-$J$22/$M$6)))/(1-(1+Q19)^(1/$M$6))+$E$20*((1-(1+Q19)^(-$J$23/$M$7)))/(1-(1+Q19)^(1/$M$7))+$E$21*((1-(1+Q19)^(-$J$24/$M$8)))/(1-(1+Q19)^(1/$M$8)) -> 446.99397 | U19: =$E$4-$E$10-$E$11*(1+R19)^(-$E$5/$L$9)-$E$13*(1+R19)^(-$H$13/$L$9)-$E$14*(1+R19)^(-$H$14/$L$9) +$E$24*((1-(1+R19)^(-$E$5/$L$9)))/(1-(1+R19)^(1/$L$9))+$E$17*((1-(1+R19)^(-$J$20/$M$4)))/(1-(1+R19)^(1/$M$4))+$E$18*((1-(1+R19)^(-$J$21/$M$5)))/(1-(1+R19)^(1/$M$5))+$E$19*((1-(1+R19)^(-$J$22/$M$6)))/(1-(1+R19)^(1/$M$6))+$E$20*((1-(1+R19)^(-$J$23/$M$7)))/(1-(1+R19)^(1/$M$7))+$E$21*((1-(1+R19)^(-$J$24/$M$8)))/(1-(1+R19)^(1/$M$8)) -> -12471.531
C20: =L7 -> semiannual | E20: 0 | F20: currency | J20: =IF($E$7=$L$4,$E$5,IF($E$7=$L$5,52/12*$E$5,IF($E$7=$L$6,13*$E$5,IF($E$7=$L$7,26*$E$5,IF($E$7=$L$8,52*$E$5))))) -> 1560 | O20: 16 | P20: =IF(S19*U19>=0,R19,P19) -> 0.055236817 | Q20: =IF(T19*U19>=0,R19,Q19) -> 0.055541992 | R20: =(P20+Q20)/2 -> 0.055389404 | S20: =$E$4-$E$10-$E$11*(1+P20)^(-$E$5/$L$9)-$E$13*(1+P20)^(-$H$13/$L$9)-$E$14*(1+P20)^(-$H$14/$L$9) +$E$24*((1-(1+P20)^(-$E$5/$L$9)))/(1-(1+P20)^(1/$L$9))+$E$17*((1-(1+P20)^(-$J$20/$M$4)))/(1-(1+P20)^(1/$M$4))+$E$18*((1-(1+P20)^(-$J$21/$M$5)))/(1-(1+P20)^(1/$M$5))+$E$19*((1-(1+P20)^(-$J$22/$M$6)))/(1-(1+P20)^(1/$M$6))+$E$20*((1-(1+P20)^(-$J$23/$M$7)))/(1-(1+P20)^(1/$M$7))+$E$21*((1-(1+P20)^(-$J$24/$M$8)))/(1-(1+P20)^(1/$M$8)) -> -12471.531 | T20: =$E$4-$E$10-$E$11*(1+Q20)^(-$E$5/$L$9)-$E$13*(1+Q20)^(-$H$13/$L$9)-$E$14*(1+Q20)^(-$H$14/$L$9) +$E$24*((1-(1+Q20)^(-$E$5/$L$9)))/(1-(1+Q20)^(1/$L$9))+$E$17*((1-(1+Q20)^(-$J$20/$M$4)))/(1-(1+Q20)^(1/$M$4))+$E$18*((1-(1+Q20)^(-$J$21/$M$5)))/(1-(1+Q20)^(1/$M$5))+$E$19*((1-(1+Q20)^(-$J$22/$M$6)))/(1-(1+Q20)^(1/$M$6))+$E$20*((1-(1+Q20)^(-$J$23/$M$7)))/(1-(1+Q20)^(1/$M$7))+$E$21*((1-(1+Q20)^(-$J$24/$M$8)))/(1-(1+Q20)^(1/$M$8)) -> 446.99397 | U20: =$E$4-$E$10-$E$11*(1+R20)^(-$E$5/$L$9)-$E$13*(1+R20)^(-$H$13/$L$9)-$E$14*(1+R20)^(-$H$14/$L$9) +$E$24*((1-(1+R20)^(-$E$5/$L$9)))/(1-(1+R20)^(1/$L$9))+$E$17*((1-(1+R20)^(-$J$20/$M$4)))/(1-(1+R20)^(1/$M$4))+$E$18*((1-(1+R20)^(-$J$21/$M$5)))/(1-(1+R20)^(1/$M$5))+$E$19*((1-(1+R20)^(-$J$22/$M$6)))/(1-(1+R20)^(1/$M$6))+$E$20*((1-(1+R20)^(-$J$23/$M$7)))/(1-(1+R20)^(1/$M$7))+$E$21*((1-(1+R20)^(-$J$24/$M$8)))/(1-(1+R20)^(1/$M$8)) -> -6003.8227
C21: =L8 -> annual | E21: 200 | F21: currency | J21: =IF($E$7=$L$4,$E$5*52/12,IF($E$7=$L$5,$E$5,IF($E$7=$L$6,3*$E$5,IF($E$7=$L$7,6*$E$5,IF($E$7=$L$8,12*$E$5))))) -> 360 | O21: 17 | P21: =IF(S20*U20>=0,R20,P20) -> 0.055389404 | Q21: =IF(T20*U20>=0,R20,Q20) -> 0.055541992 | R21: =(P21+Q21)/2 -> 0.055465698 | S21: =$E$4-$E$10-$E$11*(1+P21)^(-$E$5/$L$9)-$E$13*(1+P21)^(-$H$13/$L$9)-$E$14*(1+P21)^(-$H$14/$L$9) +$E$24*((1-(1+P21)^(-$E$5/$L$9)))/(1-(1+P21)^(1/$L$9))+$E$17*((1-(1+P21)^(-$J$20/$M$4)))/(1-(1+P21)^(1/$M$4))+$E$18*((1-(1+P21)^(-$J$21/$M$5)))/(1-(1+P21)^(1/$M$5))+$E$19*((1-(1+P21)^(-$J$22/$M$6)))/(1-(1+P21)^(1/$M$6))+$E$20*((1-(1+P21)^(-$J$23/$M$7)))/(1-(1+P21)^(1/$M$7))+$E$21*((1-(1+P21)^(-$J$24/$M$8)))/(1-(1+P21)^(1/$M$8)) -> -6003.8227 | T21: =$E$4-$E$10-$E$11*(1+Q21)^(-$E$5/$L$9)-$E$13*(1+Q21)^(-$H$13/$L$9)-$E$14*(1+Q21)^(-$H$14/$L$9) +$E$24*((1-(1+Q21)^(-$E$5/$L$9)))/(1-(1+Q21)^(1/$L$9))+$E$17*((1-(1+Q21)^(-$J$20/$M$4)))/(1-(1+Q21)^(1/$M$4))+$E$18*((1-(1+Q21)^(-$J$21/$M$5)))/(1-(1+Q21)^(1/$M$5))+$E$19*((1-(1+Q21)^(-$J$22/$M$6)))/(1-(1+Q21)^(1/$M$6))+$E$20*((1-(1+Q21)^(-$J$23/$M$7)))/(1-(1+Q21)^(1/$M$7))+$E$21*((1-(1+Q21)^(-$J$24/$M$8)))/(1-(1+Q21)^(1/$M$8)) -> 446.99397 | U21: =$E$4-$E$10-$E$11*(1+R21)^(-$E$5/$L$9)-$E$13*(1+R21)^(-$H$13/$L$9)-$E$14*(1+R21)^(-$H$14/$L$9) +$E$24*((1-(1+R21)^(-$E$5/$L$9)))/(1-(1+R21)^(1/$L$9))+$E$17*((1-(1+R21)^(-$J$20/$M$4)))/(1-(1+R21)^(1/$M$4))+$E$18*((1-(1+R21)^(-$J$21/$M$5)))/(1-(1+R21)^(1/$M$5))+$E$19*((1-(1+R21)^(-$J$22/$M$6)))/(1-(1+R21)^(1/$M$6))+$E$20*((1-(1+R21)^(-$J$23/$M$7)))/(1-(1+R21)^(1/$M$7))+$E$21*((1-(1+R21)^(-$J$24/$M$8)))/(1-(1+R21)^(1/$M$8)) -> -2776.3064
J22: =IF($E$7=$L$4,$E$5/13,IF($E$7=$L$5,$E$5/3,IF($E$7=$L$6,$E$5,IF($E$7=$L$7,2*$E$5,IF($E$7=$L$8,4*$E$5))))) -> 120 | O22: 18 | P22: =IF(S21*U21>=0,R21,P21) -> 0.055465698 | Q22: =IF(T21*U21>=0,R21,Q21) -> 0.055541992 | R22: =(P22+Q22)/2 -> 0.055503845 | S22: =$E$4-$E$10-$E$11*(1+P22)^(-$E$5/$L$9)-$E$13*(1+P22)^(-$H$13/$L$9)-$E$14*(1+P22)^(-$H$14/$L$9) +$E$24*((1-(1+P22)^(-$E$5/$L$9)))/(1-(1+P22)^(1/$L$9))+$E$17*((1-(1+P22)^(-$J$20/$M$4)))/(1-(1+P22)^(1/$M$4))+$E$18*((1-(1+P22)^(-$J$21/$M$5)))/(1-(1+P22)^(1/$M$5))+$E$19*((1-(1+P22)^(-$J$22/$M$6)))/(1-(1+P22)^(1/$M$6))+$E$20*((1-(1+P22)^(-$J$23/$M$7)))/(1-(1+P22)^(1/$M$7))+$E$21*((1-(1+P22)^(-$J$24/$M$8)))/(1-(1+P22)^(1/$M$8)) -> -2776.3064 | T22: =$E$4-$E$10-$E$11*(1+Q22)^(-$E$5/$L$9)-$E$13*(1+Q22)^(-$H$13/$L$9)-$E$14*(1+Q22)^(-$H$14/$L$9) +$E$24*((1-(1+Q22)^(-$E$5/$L$9)))/(1-(1+Q22)^(1/$L$9))+$E$17*((1-(1+Q22)^(-$J$20/$M$4)))/(1-(1+Q22)^(1/$M$4))+$E$18*((1-(1+Q22)^(-$J$21/$M$5)))/(1-(1+Q22)^(1/$M$5))+$E$19*((1-(1+Q22)^(-$J$22/$M$6)))/(1-(1+Q22)^(1/$M$6))+$E$20*((1-(1+Q22)^(-$J$23/$M$7)))/(1-(1+Q22)^(1/$M$7))+$E$21*((1-(1+Q22)^(-$J$24/$M$8)))/(1-(1+Q22)^(1/$M$8)) -> 446.99397 | U22: =$E$4-$E$10-$E$11*(1+R22)^(-$E$5/$L$9)-$E$13*(1+R22)^(-$H$13/$L$9)-$E$14*(1+R22)^(-$H$14/$L$9) +$E$24*((1-(1+R22)^(-$E$5/$L$9)))/(1-(1+R22)^(1/$L$9))+$E$17*((1-(1+R22)^(-$J$20/$M$4)))/(1-(1+R22)^(1/$M$4))+$E$18*((1-(1+R22)^(-$J$21/$M$5)))/(1-(1+R22)^(1/$M$5))+$E$19*((1-(1+R22)^(-$J$22/$M$6)))/(1-(1+R22)^(1/$M$6))+$E$20*((1-(1+R22)^(-$J$23/$M$7)))/(1-(1+R22)^(1/$M$7))+$E$21*((1-(1+R22)^(-$J$24/$M$8)))/(1-(1+R22)^(1/$M$8)) -> -1164.1296
J23: =IF($E$7=$L$4,$E$5/26,IF($E$7=$L$5,$E$5/6,IF($E$7=$L$6,$E$5/2,IF($E$7=$L$7,$E$5,IF($E$7=$L$8,2*$E$5))))) -> 60 | O23: 19 | P23: =IF(S22*U22>=0,R22,P22) -> 0.055503845 | Q23: =IF(T22*U22>=0,R22,Q22) -> 0.055541992 | R23: =(P23+Q23)/2 -> 0.055522919 | S23: =$E$4-$E$10-$E$11*(1+P23)^(-$E$5/$L$9)-$E$13*(1+P23)^(-$H$13/$L$9)-$E$14*(1+P23)^(-$H$14/$L$9) +$E$24*((1-(1+P23)^(-$E$5/$L$9)))/(1-(1+P23)^(1/$L$9))+$E$17*((1-(1+P23)^(-$J$20/$M$4)))/(1-(1+P23)^(1/$M$4))+$E$18*((1-(1+P23)^(-$J$21/$M$5)))/(1-(1+P23)^(1/$M$5))+$E$19*((1-(1+P23)^(-$J$22/$M$6)))/(1-(1+P23)^(1/$M$6))+$E$20*((1-(1+P23)^(-$J$23/$M$7)))/(1-(1+P23)^(1/$M$7))+$E$21*((1-(1+P23)^(-$J$24/$M$8)))/(1-(1+P23)^(1/$M$8)) -> -1164.1296 | T23: =$E$4-$E$10-$E$11*(1+Q23)^(-$E$5/$L$9)-$E$13*(1+Q23)^(-$H$13/$L$9)-$E$14*(1+Q23)^(-$H$14/$L$9) +$E$24*((1-(1+Q23)^(-$E$5/$L$9)))/(1-(1+Q23)^(1/$L$9))+$E$17*((1-(1+Q23)^(-$J$20/$M$4)))/(1-(1+Q23)^(1/$M$4))+$E$18*((1-(1+Q23)^(-$J$21/$M$5)))/(1-(1+Q23)^(1/$M$5))+$E$19*((1-(1+Q23)^(-$J$22/$M$6)))/(1-(1+Q23)^(1/$M$6))+$E$20*((1-(1+Q23)^(-$J$23/$M$7)))/(1-(1+Q23)^(1/$M$7))+$E$21*((1-(1+Q23)^(-$J$24/$M$8)))/(1-(1+Q23)^(1/$M$8)) -> 446.99397 | U23: =$E$4-$E$10-$E$11*(1+R23)^(-$E$5/$L$9)-$E$13*(1+R23)^(-$H$13/$L$9)-$E$14*(1+R23)^(-$H$14/$L$9) +$E$24*((1-(1+R23)^(-$E$5/$L$9)))/(1-(1+R23)^(1/$L$9))+$E$17*((1-(1+R23)^(-$J$20/$M$4)))/(1-(1+R23)^(1/$M$4))+$E$18*((1-(1+R23)^(-$J$21/$M$5)))/(1-(1+R23)^(1/$M$5))+$E$19*((1-(1+R23)^(-$J$22/$M$6)))/(1-(1+R23)^(1/$M$6))+$E$20*((1-(1+R23)^(-$J$23/$M$7)))/(1-(1+R23)^(1/$M$7))+$E$21*((1-(1+R23)^(-$J$24/$M$8)))/(1-(1+R23)^(1/$M$8)) -> -358.43624
C24: fee-free payment | E24: =IF(E6=0,E4/E5,IF(E6>0,E4*L10*((1+L10)^E5)/((1+L10)^E5-1),"úrok nesmí být záporný")) -> 22461.232 | F24: currency | J24: =IF($E$7=$L$4,$E$5/52,IF($E$7=$L$5,$E$5/12,IF($E$7=$L$6,$E$5/4,IF($E$7=$L$7,$E$5/2,IF($E$7=$L$8,1*$E$5))))) -> 30 | O24: 20 | P24: =IF(S23*U23>=0,R23,P23) -> 0.055522919 | Q24: =IF(T23*U23>=0,R23,Q23) -> 0.055541992 | R24: =(P24+Q24)/2 -> 0.055532456 | S24: =$E$4-$E$10-$E$11*(1+P24)^(-$E$5/$L$9)-$E$13*(1+P24)^(-$H$13/$L$9)-$E$14*(1+P24)^(-$H$14/$L$9) +$E$24*((1-(1+P24)^(-$E$5/$L$9)))/(1-(1+P24)^(1/$L$9))+$E$17*((1-(1+P24)^(-$J$20/$M$4)))/(1-(1+P24)^(1/$M$4))+$E$18*((1-(1+P24)^(-$J$21/$M$5)))/(1-(1+P24)^(1/$M$5))+$E$19*((1-(1+P24)^(-$J$22/$M$6)))/(1-(1+P24)^(1/$M$6))+$E$20*((1-(1+P24)^(-$J$23/$M$7)))/(1-(1+P24)^(1/$M$7))+$E$21*((1-(1+P24)^(-$J$24/$M$8)))/(1-(1+P24)^(1/$M$8)) -> -358.43624 | T24: =$E$4-$E$10-$E$11*(1+Q24)^(-$E$5/$L$9)-$E$13*(1+Q24)^(-$H$13/$L$9)-$E$14*(1+Q24)^(-$H$14/$L$9) +$E$24*((1-(1+Q24)^(-$E$5/$L$9)))/(1-(1+Q24)^(1/$L$9))+$E$17*((1-(1+Q24)^(-$J$20/$M$4)))/(1-(1+Q24)^(1/$M$4))+$E$18*((1-(1+Q24)^(-$J$21/$M$5)))/(1-(1+Q24)^(1/$M$5))+$E$19*((1-(1+Q24)^(-$J$22/$M$6)))/(1-(1+Q24)^(1/$M$6))+$E$20*((1-(1+Q24)^(-$J$23/$M$7)))/(1-(1+Q24)^(1/$M$7))+$E$21*((1-(1+Q24)^(-$J$24/$M$8)))/(1-(1+Q24)^(1/$M$8)) -> 446.99397 | U24: =$E$4-$E$10-$E$11*(1+R24)^(-$E$5/$L$9)-$E$13*(1+R24)^(-$H$13/$L$9)-$E$14*(1+R24)^(-$H$14/$L$9) +$E$24*((1-(1+R24)^(-$E$5/$L$9)))/(1-(1+R24)^(1/$L$9))+$E$17*((1-(1+R24)^(-$J$20/$M$4)))/(1-(1+R24)^(1/$M$4))+$E$18*((1-(1+R24)^(-$J$21/$M$5)))/(1-(1+R24)^(1/$M$5))+$E$19*((1-(1+R24)^(-$J$22/$M$6)))/(1-(1+R24)^(1/$M$6))+$E$20*((1-(1+R24)^(-$J$23/$M$7)))/(1-(1+R24)^(1/$M$7))+$E$21*((1-(1+R24)^(-$J$24/$M$8)))/(1-(1+R24)^(1/$M$8)) -> 44.311755
C25: APR | E25: =IF(C28=0,0,IF(R104 >0,R104*100)) -> 5.5531406 | F25: % | O25: 21 | P25: =IF(S24*U24>=0,R24,P24) -> 0.055522919 | Q25: =IF(T24*U24>=0,R24,Q24) -> 0.055532456 | R25: =(P25+Q25)/2 -> 0.055527687 | S25: =$E$4-$E$10-$E$11*(1+P25)^(-$E$5/$L$9)-$E$13*(1+P25)^(-$H$13/$L$9)-$E$14*(1+P25)^(-$H$14/$L$9) +$E$24*((1-(1+P25)^(-$E$5/$L$9)))/(1-(1+P25)^(1/$L$9))+$E$17*((1-(1+P25)^(-$J$20/$M$4)))/(1-(1+P25)^(1/$M$4))+$E$18*((1-(1+P25)^(-$J$21/$M$5)))/(1-(1+P25)^(1/$M$5))+$E$19*((1-(1+P25)^(-$J$22/$M$6)))/(1-(1+P25)^(1/$M$6))+$E$20*((1-(1+P25)^(-$J$23/$M$7)))/(1-(1+P25)^(1/$M$7))+$E$21*((1-(1+P25)^(-$J$24/$M$8)))/(1-(1+P25)^(1/$M$8)) -> -358.43624 | T25: =$E$4-$E$10-$E$11*(1+Q25)^(-$E$5/$L$9)-$E$13*(1+Q25)^(-$H$13/$L$9)-$E$14*(1+Q25)^(-$H$14/$L$9) +$E$24*((1-(1+Q25)^(-$E$5/$L$9)))/(1-(1+Q25)^(1/$L$9))+$E$17*((1-(1+Q25)^(-$J$20/$M$4)))/(1-(1+Q25)^(1/$M$4))+$E$18*((1-(1+Q25)^(-$J$21/$M$5)))/(1-(1+Q25)^(1/$M$5))+$E$19*((1-(1+Q25)^(-$J$22/$M$6)))/(1-(1+Q25)^(1/$M$6))+$E$20*((1-(1+Q25)^(-$J$23/$M$7)))/(1-(1+Q25)^(1/$M$7))+$E$21*((1-(1+Q25)^(-$J$24/$M$8)))/(1-(1+Q25)^(1/$M$8)) -> 44.311755 | U25: =$E$4-$E$10-$E$11*(1+R25)^(-$E$5/$L$9)-$E$13*(1+R25)^(-$H$13/$L$9)-$E$14*(1+R25)^(-$H$14/$L$9) +$E$24*((1-(1+R25)^(-$E$5/$L$9)))/(1-(1+R25)^(1/$L$9))+$E$17*((1-(1+R25)^(-$J$20/$M$4)))/(1-(1+R25)^(1/$M$4))+$E$18*((1-(1+R25)^(-$J$21/$M$5)))/(1-(1+R25)^(1/$M$5))+$E$19*((1-(1+R25)^(-$J$22/$M$6)))/(1-(1+R25)^(1/$M$6))+$E$20*((1-(1+R25)^(-$J$23/$M$7)))/(1-(1+R25)^(1/$M$7))+$E$21*((1-(1+R25)^(-$J$24/$M$8)))/(1-(1+R25)^(1/$M$8)) -> -157.05402
O26: 22 | P26: =IF(S25*U25>=0,R25,P25) -> 0.055527687 | Q26: =IF(T25*U25>=0,R25,Q25) -> 0.055532456 | R26: =(P26+Q26)/2 -> 0.055530071 | S26: =$E$4-$E$10-$E$11*(1+P26)^(-$E$5/$L$9)-$E$13*(1+P26)^(-$H$13/$L$9)-$E$14*(1+P26)^(-$H$14/$L$9) +$E$24*((1-(1+P26)^(-$E$5/$L$9)))/(1-(1+P26)^(1/$L$9))+$E$17*((1-(1+P26)^(-$J$20/$M$4)))/(1-(1+P26)^(1/$M$4))+$E$18*((1-(1+P26)^(-$J$21/$M$5)))/(1-(1+P26)^(1/$M$5))+$E$19*((1-(1+P26)^(-$J$22/$M$6)))/(1-(1+P26)^(1/$M$6))+$E$20*((1-(1+P26)^(-$J$23/$M$7)))/(1-(1+P26)^(1/$M$7))+$E$21*((1-(1+P26)^(-$J$24/$M$8)))/(1-(1+P26)^(1/$M$8)) -> -157.05402 | T26: =$E$4-$E$10-$E$11*(1+Q26)^(-$E$5/$L$9)-$E$13*(1+Q26)^(-$H$13/$L$9)-$E$14*(1+Q26)^(-$H$14/$L$9) +$E$24*((1-(1+Q26)^(-$E$5/$L$9)))/(1-(1+Q26)^(1/$L$9))+$E$17*((1-(1+Q26)^(-$J$20/$M$4)))/(1-(1+Q26)^(1/$M$4))+$E$18*((1-(1+Q26)^(-$J$21/$M$5)))/(1-(1+Q26)^(1/$M$5))+$E$19*((1-(1+Q26)^(-$J$22/$M$6)))/(1-(1+Q26)^(1/$M$6))+$E$20*((1-(1+Q26)^(-$J$23/$M$7)))/(1-(1+Q26)^(1/$M$7))+$E$21*((1-(1+Q26)^(-$J$24/$M$8)))/(1-(1+Q26)^(1/$M$8)) -> 44.311755 | U26: =$E$4-$E$10-$E$11*(1+R26)^(-$E$5/$L$9)-$E$13*(1+R26)^(-$H$13/$L$9)-$E$14*(1+R26)^(-$H$14/$L$9) +$E$24*((1-(1+R26)^(-$E$5/$L$9)))/(1-(1+R26)^(1/$L$9))+$E$17*((1-(1+R26)^(-$J$20/$M$4)))/(1-(1+R26)^(1/$M$4))+$E$18*((1-(1+R26)^(-$J$21/$M$5)))/(1-(1+R26)^(1/$M$5))+$E$19*((1-(1+R26)^(-$J$22/$M$6)))/(1-(1+R26)^(1/$M$6))+$E$20*((1-(1+R26)^(-$J$23/$M$7)))/(1-(1+R26)^(1/$M$7))+$E$21*((1-(1+R26)^(-$J$24/$M$8)))/(1-(1+R26)^(1/$M$8)) -> -56.369076
O27: 23 | P27: =IF(S26*U26>=0,R26,P26) -> 0.055530071 | Q27: =IF(T26*U26>=0,R26,Q26) -> 0.055532456 | R27: =(P27+Q27)/2 -> 0.055531263 | S27: =$E$4-$E$10-$E$11*(1+P27)^(-$E$5/$L$9)-$E$13*(1+P27)^(-$H$13/$L$9)-$E$14*(1+P27)^(-$H$14/$L$9) +$E$24*((1-(1+P27)^(-$E$5/$L$9)))/(1-(1+P27)^(1/$L$9))+$E$17*((1-(1+P27)^(-$J$20/$M$4)))/(1-(1+P27)^(1/$M$4))+$E$18*((1-(1+P27)^(-$J$21/$M$5)))/(1-(1+P27)^(1/$M$5))+$E$19*((1-(1+P27)^(-$J$22/$M$6)))/(1-(1+P27)^(1/$M$6))+$E$20*((1-(1+P27)^(-$J$23/$M$7)))/(1-(1+P27)^(1/$M$7))+$E$21*((1-(1+P27)^(-$J$24/$M$8)))/(1-(1+P27)^(1/$M$8)) -> -56.369076 | T27: =$E$4-$E$10-$E$11*(1+Q27)^(-$E$5/$L$9)-$E$13*(1+Q27)^(-$H$13/$L$9)-$E$14*(1+Q27)^(-$H$14/$L$9) +$E$24*((1-(1+Q27)^(-$E$5/$L$9)))/(1-(1+Q27)^(1/$L$9))+$E$17*((1-(1+Q27)^(-$J$20/$M$4)))/(1-(1+Q27)^(1/$M$4))+$E$18*((1-(1+Q27)^(-$J$21/$M$5)))/(1-(1+Q27)^(1/$M$5))+$E$19*((1-(1+Q27)^(-$J$22/$M$6)))/(1-(1+Q27)^(1/$M$6))+$E$20*((1-(1+Q27)^(-$J$23/$M$7)))/(1-(1+Q27)^(1/$M$7))+$E$21*((1-(1+Q27)^(-$J$24/$M$8)))/(1-(1+Q27)^(1/$M$8)) -> 44.311755 | U27: =$E$4-$E$10-$E$11*(1+R27)^(-$E$5/$L$9)-$E$13*(1+R27)^(-$H$13/$L$9)-$E$14*(1+R27)^(-$H$14/$L$9) +$E$24*((1-(1+R27)^(-$E$5/$L$9)))/(1-(1+R27)^(1/$L$9))+$E$17*((1-(1+R27)^(-$J$20/$M$4)))/(1-(1+R27)^(1/$M$4))+$E$18*((1-(1+R27)^(-$J$21/$M$5)))/(1-(1+R27)^(1/$M$5))+$E$19*((1-(1+R27)^(-$J$22/$M$6)))/(1-(1+R27)^(1/$M$6))+$E$20*((1-(1+R27)^(-$J$23/$M$7)))/(1-(1+R27)^(1/$M$7))+$E$21*((1-(1+R27)^(-$J$24/$M$8)))/(1-(1+R27)^(1/$M$8)) -> -6.0281467
C28: =E6+E10+E11+E13+E14+E17+E18+E19+E20+E21 -> 4700.054 | E28: =IF(C17=E7,E17,IF(C18=E7,E18,IF(C19=E7,E19,IF(C20=E7,E20,IF(C21=E7,E21))))) -> 0 | O28: 24 | P28: =IF(S27*U27>=0,R27,P27) -> 0.055531263 | Q28: =IF(T27*U27>=0,R27,Q27) -> 0.055532456 | R28: =(P28+Q28)/2 -> 0.055531859 | S28: =$E$4-$E$10-$E$11*(1+P28)^(-$E$5/$L$9)-$E$13*(1+P28)^(-$H$13/$L$9)-$E$14*(1+P28)^(-$H$14/$L$9) +$E$24*((1-(1+P28)^(-$E$5/$L$9)))/(1-(1+P28)^(1/$L$9))+$E$17*((1-(1+P28)^(-$J$20/$M$4)))/(1-(1+P28)^(1/$M$4))+$E$18*((1-(1+P28)^(-$J$21/$M$5)))/(1-(1+P28)^(1/$M$5))+$E$19*((1-(1+P28)^(-$J$22/$M$6)))/(1-(1+P28)^(1/$M$6))+$E$20*((1-(1+P28)^(-$J$23/$M$7)))/(1-(1+P28)^(1/$M$7))+$E$21*((1-(1+P28)^(-$J$24/$M$8)))/(1-(1+P28)^(1/$M$8)) -> -6.0281467 | T28: =$E$4-$E$10-$E$11*(1+Q28)^(-$E$5/$L$9)-$E$13*(1+Q28)^(-$H$13/$L$9)-$E$14*(1+Q28)^(-$H$14/$L$9) +$E$24*((1-(1+Q28)^(-$E$5/$L$9)))/(1-(1+Q28)^(1/$L$9))+$E$17*((1-(1+Q28)^(-$J$20/$M$4)))/(1-(1+Q28)^(1/$M$4))+$E$18*((1-(1+Q28)^(-$J$21/$M$5)))/(1-(1+Q28)^(1/$M$5))+$E$19*((1-(1+Q28)^(-$J$22/$M$6)))/(1-(1+Q28)^(1/$M$6))+$E$20*((1-(1+Q28)^(-$J$23/$M$7)))/(1-(1+Q28)^(1/$M$7))+$E$21*((1-(1+Q28)^(-$J$24/$M$8)))/(1-(1+Q28)^(1/$M$8)) -> 44.311755 | U28: =$E$4-$E$10-$E$11*(1+R28)^(-$E$5/$L$9)-$E$13*(1+R28)^(-$H$13/$L$9)-$E$14*(1+R28)^(-$H$14/$L$9) +$E$24*((1-(1+R28)^(-$E$5/$L$9)))/(1-(1+R28)^(1/$L$9))+$E$17*((1-(1+R28)^(-$J$20/$M$4)))/(1-(1+R28)^(1/$M$4))+$E$18*((1-(1+R28)^(-$J$21/$M$5)))/(1-(1+R28)^(1/$M$5))+$E$19*((1-(1+R28)^(-$J$22/$M$6)))/(1-(1+R28)^(1/$M$6))+$E$20*((1-(1+R28)^(-$J$23/$M$7)))/(1-(1+R28)^(1/$M$7))+$E$21*((1-(1+R28)^(-$J$24/$M$8)))/(1-(1+R28)^(1/$M$8)) -> 19.141933
O29: 25 | P29: =IF(S28*U28>=0,R28,P28) -> 0.055531263 | Q29: =IF(T28*U28>=0,R28,Q28) -> 0.055531859 | R29: =(P29+Q29)/2 -> 0.055531561 | S29: =$E$4-$E$10-$E$11*(1+P29)^(-$E$5/$L$9)-$E$13*(1+P29)^(-$H$13/$L$9)-$E$14*(1+P29)^(-$H$14/$L$9) +$E$24*((1-(1+P29)^(-$E$5/$L$9)))/(1-(1+P29)^(1/$L$9))+$E$17*((1-(1+P29)^(-$J$20/$M$4)))/(1-(1+P29)^(1/$M$4))+$E$18*((1-(1+P29)^(-$J$21/$M$5)))/(1-(1+P29)^(1/$M$5))+$E$19*((1-(1+P29)^(-$J$22/$M$6)))/(1-(1+P29)^(1/$M$6))+$E$20*((1-(1+P29)^(-$J$23/$M$7)))/(1-(1+P29)^(1/$M$7))+$E$21*((1-(1+P29)^(-$J$24/$M$8)))/(1-(1+P29)^(1/$M$8)) -> -6.0281467 | T29: =$E$4-$E$10-$E$11*(1+Q29)^(-$E$5/$L$9)-$E$13*(1+Q29)^(-$H$13/$L$9)-$E$14*(1+Q29)^(-$H$14/$L$9) +$E$24*((1-(1+Q29)^(-$E$5/$L$9)))/(1-(1+Q29)^(1/$L$9))+$E$17*((1-(1+Q29)^(-$J$20/$M$4)))/(1-(1+Q29)^(1/$M$4))+$E$18*((1-(1+Q29)^(-$J$21/$M$5)))/(1-(1+Q29)^(1/$M$5))+$E$19*((1-(1+Q29)^(-$J$22/$M$6)))/(1-(1+Q29)^(1/$M$6))+$E$20*((1-(1+Q29)^(-$J$23/$M$7)))/(1-(1+Q29)^(1/$M$7))+$E$21*((1-(1+Q29)^(-$J$24/$M$8)))/(1-(1+Q29)^(1/$M$8)) -> 19.141933 | U29: =$E$4-$E$10-$E$11*(1+R29)^(-$E$5/$L$9)-$E$13*(1+R29)^(-$H$13/$L$9)-$E$14*(1+R29)^(-$H$14/$L$9) +$E$24*((1-(1+R29)^(-$E$5/$L$9)))/(1-(1+R29)^(1/$L$9))+$E$17*((1-(1+R29)^(-$J$20/$M$4)))/(1-(1+R29)^(1/$M$4))+$E$18*((1-(1+R29)^(-$J$21/$M$5)))/(1-(1+R29)^(1/$M$5))+$E$19*((1-(1+R29)^(-$J$22/$M$6)))/(1-(1+R29)^(1/$M$6))+$E$20*((1-(1+R29)^(-$J$23/$M$7)))/(1-(1+R29)^(1/$M$7))+$E$21*((1-(1+R29)^(-$J$24/$M$8)))/(1-(1+R29)^(1/$M$8)) -> 6.5569249
O30: 26 | P30: =IF(S29*U29>=0,R29,P29) -> 0.055531263 | Q30: =IF(T29*U29>=0,R29,Q29) -> 0.055531561 | R30: =(P30+Q30)/2 -> 0.055531412 | S30: =$E$4-$E$10-$E$11*(1+P30)^(-$E$5/$L$9)-$E$13*(1+P30)^(-$H$13/$L$9)-$E$14*(1+P30)^(-$H$14/$L$9) +$E$24*((1-(1+P30)^(-$E$5/$L$9)))/(1-(1+P30)^(1/$L$9))+$E$17*((1-(1+P30)^(-$J$20/$M$4)))/(1-(1+P30)^(1/$M$4))+$E$18*((1-(1+P30)^(-$J$21/$M$5)))/(1-(1+P30)^(1/$M$5))+$E$19*((1-(1+P30)^(-$J$22/$M$6)))/(1-(1+P30)^(1/$M$6))+$E$20*((1-(1+P30)^(-$J$23/$M$7)))/(1-(1+P30)^(1/$M$7))+$E$21*((1-(1+P30)^(-$J$24/$M$8)))/(1-(1+P30)^(1/$M$8)) -> -6.0281467 | T30: =$E$4-$E$10-$E$11*(1+Q30)^(-$E$5/$L$9)-$E$13*(1+Q30)^(-$H$13/$L$9)-$E$14*(1+Q30)^(-$H$14/$L$9) +$E$24*((1-(1+Q30)^(-$E$5/$L$9)))/(1-(1+Q30)^(1/$L$9))+$E$17*((1-(1+Q30)^(-$J$20/$M$4)))/(1-(1+Q30)^(1/$M$4))+$E$18*((1-(1+Q30)^(-$J$21/$M$5)))/(1-(1+Q30)^(1/$M$5))+$E$19*((1-(1+Q30)^(-$J$22/$M$6)))/(1-(1+Q30)^(1/$M$6))+$E$20*((1-(1+Q30)^(-$J$23/$M$7)))/(1-(1+Q30)^(1/$M$7))+$E$21*((1-(1+Q30)^(-$J$24/$M$8)))/(1-(1+Q30)^(1/$M$8)) -> 6.5569249 | U30: =$E$4-$E$10-$E$11*(1+R30)^(-$E$5/$L$9)-$E$13*(1+R30)^(-$H$13/$L$9)-$E$14*(1+R30)^(-$H$14/$L$9) +$E$24*((1-(1+R30)^(-$E$5/$L$9)))/(1-(1+R30)^(1/$L$9))+$E$17*((1-(1+R30)^(-$J$20/$M$4)))/(1-(1+R30)^(1/$M$4))+$E$18*((1-(1+R30)^(-$J$21/$M$5)))/(1-(1+R30)^(1/$M$5))+$E$19*((1-(1+R30)^(-$J$22/$M$6)))/(1-(1+R30)^(1/$M$6))+$E$20*((1-(1+R30)^(-$J$23/$M$7)))/(1-(1+R30)^(1/$M$7))+$E$21*((1-(1+R30)^(-$J$24/$M$8)))/(1-(1+R30)^(1/$M$8)) -> 0.26439707
O31: 27 | P31: =IF(S30*U30>=0,R30,P30) -> 0.055531263 | Q31: =IF(T30*U30>=0,R30,Q30) -> 0.055531412 | R31: =(P31+Q31)/2 -> 0.055531338 | S31: =$E$4-$E$10-$E$11*(1+P31)^(-$E$5/$L$9)-$E$13*(1+P31)^(-$H$13/$L$9)-$E$14*(1+P31)^(-$H$14/$L$9) +$E$24*((1-(1+P31)^(-$E$5/$L$9)))/(1-(1+P31)^(1/$L$9))+$E$17*((1-(1+P31)^(-$J$20/$M$4)))/(1-(1+P31)^(1/$M$4))+$E$18*((1-(1+P31)^(-$J$21/$M$5)))/(1-(1+P31)^(1/$M$5))+$E$19*((1-(1+P31)^(-$J$22/$M$6)))/(1-(1+P31)^(1/$M$6))+$E$20*((1-(1+P31)^(-$J$23/$M$7)))/(1-(1+P31)^(1/$M$7))+$E$21*((1-(1+P31)^(-$J$24/$M$8)))/(1-(1+P31)^(1/$M$8)) -> -6.0281467 | T31: =$E$4-$E$10-$E$11*(1+Q31)^(-$E$5/$L$9)-$E$13*(1+Q31)^(-$H$13/$L$9)-$E$14*(1+Q31)^(-$H$14/$L$9) +$E$24*((1-(1+Q31)^(-$E$5/$L$9)))/(1-(1+Q31)^(1/$L$9))+$E$17*((1-(1+Q31)^(-$J$20/$M$4)))/(1-(1+Q31)^(1/$M$4))+$E$18*((1-(1+Q31)^(-$J$21/$M$5)))/(1-(1+Q31)^(1/$M$5))+$E$19*((1-(1+Q31)^(-$J$22/$M$6)))/(1-(1+Q31)^(1/$M$6))+$E$20*((1-(1+Q31)^(-$J$23/$M$7)))/(1-(1+Q31)^(1/$M$7))+$E$21*((1-(1+Q31)^(-$J$24/$M$8)))/(1-(1+Q31)^(1/$M$8)) -> 0.26439707 | U31: =$E$4-$E$10-$E$11*(1+R31)^(-$E$5/$L$9)-$E$13*(1+R31)^(-$H$13/$L$9)-$E$14*(1+R31)^(-$H$14/$L$9) +$E$24*((1-(1+R31)^(-$E$5/$L$9)))/(1-(1+R31)^(1/$L$9))+$E$17*((1-(1+R31)^(-$J$20/$M$4)))/(1-(1+R31)^(1/$M$4))+$E$18*((1-(1+R31)^(-$J$21/$M$5)))/(1-(1+R31)^(1/$M$5))+$E$19*((1-(1+R31)^(-$J$22/$M$6)))/(1-(1+R31)^(1/$M$6))+$E$20*((1-(1+R31)^(-$J$23/$M$7)))/(1-(1+R31)^(1/$M$7))+$E$21*((1-(1+R31)^(-$J$24/$M$8)))/(1-(1+R31)^(1/$M$8)) -> -2.8818729
O32: 28 | P32: =IF(S31*U31>=0,R31,P31) -> 0.055531338 | Q32: =IF(T31*U31>=0,R31,Q31) -> 0.055531412 | R32: =(P32+Q32)/2 -> 0.055531375 | S32: =$E$4-$E$10-$E$11*(1+P32)^(-$E$5/$L$9)-$E$13*(1+P32)^(-$H$13/$L$9)-$E$14*(1+P32)^(-$H$14/$L$9) +$E$24*((1-(1+P32)^(-$E$5/$L$9)))/(1-(1+P32)^(1/$L$9))+$E$17*((1-(1+P32)^(-$J$20/$M$4)))/(1-(1+P32)^(1/$M$4))+$E$18*((1-(1+P32)^(-$J$21/$M$5)))/(1-(1+P32)^(1/$M$5))+$E$19*((1-(1+P32)^(-$J$22/$M$6)))/(1-(1+P32)^(1/$M$6))+$E$20*((1-(1+P32)^(-$J$23/$M$7)))/(1-(1+P32)^(1/$M$7))+$E$21*((1-(1+P32)^(-$J$24/$M$8)))/(1-(1+P32)^(1/$M$8)) -> -2.8818729 | T32: =$E$4-$E$10-$E$11*(1+Q32)^(-$E$5/$L$9)-$E$13*(1+Q32)^(-$H$13/$L$9)-$E$14*(1+Q32)^(-$H$14/$L$9) +$E$24*((1-(1+Q32)^(-$E$5/$L$9)))/(1-(1+Q32)^(1/$L$9))+$E$17*((1-(1+Q32)^(-$J$20/$M$4)))/(1-(1+Q32)^(1/$M$4))+$E$18*((1-(1+Q32)^(-$J$21/$M$5)))/(1-(1+Q32)^(1/$M$5))+$E$19*((1-(1+Q32)^(-$J$22/$M$6)))/(1-(1+Q32)^(1/$M$6))+$E$20*((1-(1+Q32)^(-$J$23/$M$7)))/(1-(1+Q32)^(1/$M$7))+$E$21*((1-(1+Q32)^(-$J$24/$M$8)))/(1-(1+Q32)^(1/$M$8)) -> 0.26439707 | U32: =$E$4-$E$10-$E$11*(1+R32)^(-$E$5/$L$9)-$E$13*(1+R32)^(-$H$13/$L$9)-$E$14*(1+R32)^(-$H$14/$L$9) +$E$24*((1-(1+R32)^(-$E$5/$L$9)))/(1-(1+R32)^(1/$L$9))+$E$17*((1-(1+R32)^(-$J$20/$M$4)))/(1-(1+R32)^(1/$M$4))+$E$18*((1-(1+R32)^(-$J$21/$M$5)))/(1-(1+R32)^(1/$M$5))+$E$19*((1-(1+R32)^(-$J$22/$M$6)))/(1-(1+R32)^(1/$M$6))+$E$20*((1-(1+R32)^(-$J$23/$M$7)))/(1-(1+R32)^(1/$M$7))+$E$21*((1-(1+R32)^(-$J$24/$M$8)))/(1-(1+R32)^(1/$M$8)) -> -1.3087373
O33: 29 | P33: =IF(S32*U32>=0,R32,P32) -> 0.055531375 | Q33: =IF(T32*U32>=0,R32,Q32) -> 0.055531412 | R33: =(P33+Q33)/2 -> 0.055531394 | S33: =$E$4-$E$10-$E$11*(1+P33)^(-$E$5/$L$9)-$E$13*(1+P33)^(-$H$13/$L$9)-$E$14*(1+P33)^(-$H$14/$L$9) +$E$24*((1-(1+P33)^(-$E$5/$L$9)))/(1-(1+P33)^(1/$L$9))+$E$17*((1-(1+P33)^(-$J$20/$M$4)))/(1-(1+P33)^(1/$M$4))+$E$18*((1-(1+P33)^(-$J$21/$M$5)))/(1-(1+P33)^(1/$M$5))+$E$19*((1-(1+P33)^(-$J$22/$M$6)))/(1-(1+P33)^(1/$M$6))+$E$20*((1-(1+P33)^(-$J$23/$M$7)))/(1-(1+P33)^(1/$M$7))+$E$21*((1-(1+P33)^(-$J$24/$M$8)))/(1-(1+P33)^(1/$M$8)) -> -1.3087373 | T33: =$E$4-$E$10-$E$11*(1+Q33)^(-$E$5/$L$9)-$E$13*(1+Q33)^(-$H$13/$L$9)-$E$14*(1+Q33)^(-$H$14/$L$9) +$E$24*((1-(1+Q33)^(-$E$5/$L$9)))/(1-(1+Q33)^(1/$L$9))+$E$17*((1-(1+Q33)^(-$J$20/$M$4)))/(1-(1+Q33)^(1/$M$4))+$E$18*((1-(1+Q33)^(-$J$21/$M$5)))/(1-(1+Q33)^(1/$M$5))+$E$19*((1-(1+Q33)^(-$J$22/$M$6)))/(1-(1+Q33)^(1/$M$6))+$E$20*((1-(1+Q33)^(-$J$23/$M$7)))/(1-(1+Q33)^(1/$M$7))+$E$21*((1-(1+Q33)^(-$J$24/$M$8)))/(1-(1+Q33)^(1/$M$8)) -> 0.26439707 | U33: =$E$4-$E$10-$E$11*(1+R33)^(-$E$5/$L$9)-$E$13*(1+R33)^(-$H$13/$L$9)-$E$14*(1+R33)^(-$H$14/$L$9) +$E$24*((1-(1+R33)^(-$E$5/$L$9)))/(1-(1+R33)^(1/$L$9))+$E$17*((1-(1+R33)^(-$J$20/$M$4)))/(1-(1+R33)^(1/$M$4))+$E$18*((1-(1+R33)^(-$J$21/$M$5)))/(1-(1+R33)^(1/$M$5))+$E$19*((1-(1+R33)^(-$J$22/$M$6)))/(1-(1+R33)^(1/$M$6))+$E$20*((1-(1+R33)^(-$J$23/$M$7)))/(1-(1+R33)^(1/$M$7))+$E$21*((1-(1+R33)^(-$J$24/$M$8)))/(1-(1+R33)^(1/$M$8)) -> -0.52216988
O34: 30 | P34: =IF(S33*U33>=0,R33,P33) -> 0.055531394 | Q34: =IF(T33*U33>=0,R33,Q33) -> 0.055531412 | R34: =(P34+Q34)/2 -> 0.055531403 | S34: =$E$4-$E$10-$E$11*(1+P34)^(-$E$5/$L$9)-$E$13*(1+P34)^(-$H$13/$L$9)-$E$14*(1+P34)^(-$H$14/$L$9) +$E$24*((1-(1+P34)^(-$E$5/$L$9)))/(1-(1+P34)^(1/$L$9))+$E$17*((1-(1+P34)^(-$J$20/$M$4)))/(1-(1+P34)^(1/$M$4))+$E$18*((1-(1+P34)^(-$J$21/$M$5)))/(1-(1+P34)^(1/$M$5))+$E$19*((1-(1+P34)^(-$J$22/$M$6)))/(1-(1+P34)^(1/$M$6))+$E$20*((1-(1+P34)^(-$J$23/$M$7)))/(1-(1+P34)^(1/$M$7))+$E$21*((1-(1+P34)^(-$J$24/$M$8)))/(1-(1+P34)^(1/$M$8)) -> -0.52216988 | T34: =$E$4-$E$10-$E$11*(1+Q34)^(-$E$5/$L$9)-$E$13*(1+Q34)^(-$H$13/$L$9)-$E$14*(1+Q34)^(-$H$14/$L$9) +$E$24*((1-(1+Q34)^(-$E$5/$L$9)))/(1-(1+Q34)^(1/$L$9))+$E$17*((1-(1+Q34)^(-$J$20/$M$4)))/(1-(1+Q34)^(1/$M$4))+$E$18*((1-(1+Q34)^(-$J$21/$M$5)))/(1-(1+Q34)^(1/$M$5))+$E$19*((1-(1+Q34)^(-$J$22/$M$6)))/(1-(1+Q34)^(1/$M$6))+$E$20*((1-(1+Q34)^(-$J$23/$M$7)))/(1-(1+Q34)^(1/$M$7))+$E$21*((1-(1+Q34)^(-$J$24/$M$8)))/(1-(1+Q34)^(1/$M$8)) -> 0.26439707 | U34: =$E$4-$E$10-$E$11*(1+R34)^(-$E$5/$L$9)-$E$13*(1+R34)^(-$H$13/$L$9)-$E$14*(1+R34)^(-$H$14/$L$9) +$E$24*((1-(1+R34)^(-$E$5/$L$9)))/(1-(1+R34)^(1/$L$9))+$E$17*((1-(1+R34)^(-$J$20/$M$4)))/(1-(1+R34)^(1/$M$4))+$E$18*((1-(1+R34)^(-$J$21/$M$5)))/(1-(1+R34)^(1/$M$5))+$E$19*((1-(1+R34)^(-$J$22/$M$6)))/(1-(1+R34)^(1/$M$6))+$E$20*((1-(1+R34)^(-$J$23/$M$7)))/(1-(1+R34)^(1/$M$7))+$E$21*((1-(1+R34)^(-$J$24/$M$8)))/(1-(1+R34)^(1/$M$8)) -> -0.12888638
O35: 31 | P35: =IF(S34*U34>=0,R34,P34) -> 0.055531403 | Q35: =IF(T34*U34>=0,R34,Q34) -> 0.055531412 | R35: =(P35+Q35)/2 -> 0.055531408 | S35: =$E$4-$E$10-$E$11*(1+P35)^(-$E$5/$L$9)-$E$13*(1+P35)^(-$H$13/$L$9)-$E$14*(1+P35)^(-$H$14/$L$9) +$E$24*((1-(1+P35)^(-$E$5/$L$9)))/(1-(1+P35)^(1/$L$9))+$E$17*((1-(1+P35)^(-$J$20/$M$4)))/(1-(1+P35)^(1/$M$4))+$E$18*((1-(1+P35)^(-$J$21/$M$5)))/(1-(1+P35)^(1/$M$5))+$E$19*((1-(1+P35)^(-$J$22/$M$6)))/(1-(1+P35)^(1/$M$6))+$E$20*((1-(1+P35)^(-$J$23/$M$7)))/(1-(1+P35)^(1/$M$7))+$E$21*((1-(1+P35)^(-$J$24/$M$8)))/(1-(1+P35)^(1/$M$8)) -> -0.12888638 | T35: =$E$4-$E$10-$E$11*(1+Q35)^(-$E$5/$L$9)-$E$13*(1+Q35)^(-$H$13/$L$9)-$E$14*(1+Q35)^(-$H$14/$L$9) +$E$24*((1-(1+Q35)^(-$E$5/$L$9)))/(1-(1+Q35)^(1/$L$9))+$E$17*((1-(1+Q35)^(-$J$20/$M$4)))/(1-(1+Q35)^(1/$M$4))+$E$18*((1-(1+Q35)^(-$J$21/$M$5)))/(1-(1+Q35)^(1/$M$5))+$E$19*((1-(1+Q35)^(-$J$22/$M$6)))/(1-(1+Q35)^(1/$M$6))+$E$20*((1-(1+Q35)^(-$J$23/$M$7)))/(1-(1+Q35)^(1/$M$7))+$E$21*((1-(1+Q35)^(-$J$24/$M$8)))/(1-(1+Q35)^(1/$M$8)) -> 0.26439707 | U35: =$E$4-$E$10-$E$11*(1+R35)^(-$E$5/$L$9)-$E$13*(1+R35)^(-$H$13/$L$9)-$E$14*(1+R35)^(-$H$14/$L$9) +$E$24*((1-(1+R35)^(-$E$5/$L$9)))/(1-(1+R35)^(1/$L$9))+$E$17*((1-(1+R35)^(-$J$20/$M$4)))/(1-(1+R35)^(1/$M$4))+$E$18*((1-(1+R35)^(-$J$21/$M$5)))/(1-(1+R35)^(1/$M$5))+$E$19*((1-(1+R35)^(-$J$22/$M$6)))/(1-(1+R35)^(1/$M$6))+$E$20*((1-(1+R35)^(-$J$23/$M$7)))/(1-(1+R35)^(1/$M$7))+$E$21*((1-(1+R35)^(-$J$24/$M$8)))/(1-(1+R35)^(1/$M$8)) -> 0.067755448
O36: 32 | P36: =IF(S35*U35>=0,R35,P35) -> 0.055531403 | Q36: =IF(T35*U35>=0,R35,Q35) -> 0.055531408 | R36: =(P36+Q36)/2 -> 0.055531405 | S36: =$E$4-$E$10-$E$11*(1+P36)^(-$E$5/$L$9)-$E$13*(1+P36)^(-$H$13/$L$9)-$E$14*(1+P36)^(-$H$14/$L$9) +$E$24*((1-(1+P36)^(-$E$5/$L$9)))/(1-(1+P36)^(1/$L$9))+$E$17*((1-(1+P36)^(-$J$20/$M$4)))/(1-(1+P36)^(1/$M$4))+$E$18*((1-(1+P36)^(-$J$21/$M$5)))/(1-(1+P36)^(1/$M$5))+$E$19*((1-(1+P36)^(-$J$22/$M$6)))/(1-(1+P36)^(1/$M$6))+$E$20*((1-(1+P36)^(-$J$23/$M$7)))/(1-(1+P36)^(1/$M$7))+$E$21*((1-(1+P36)^(-$J$24/$M$8)))/(1-(1+P36)^(1/$M$8)) -> -0.12888638 | T36: =$E$4-$E$10-$E$11*(1+Q36)^(-$E$5/$L$9)-$E$13*(1+Q36)^(-$H$13/$L$9)-$E$14*(1+Q36)^(-$H$14/$L$9) +$E$24*((1-(1+Q36)^(-$E$5/$L$9)))/(1-(1+Q36)^(1/$L$9))+$E$17*((1-(1+Q36)^(-$J$20/$M$4)))/(1-(1+Q36)^(1/$M$4))+$E$18*((1-(1+Q36)^(-$J$21/$M$5)))/(1-(1+Q36)^(1/$M$5))+$E$19*((1-(1+Q36)^(-$J$22/$M$6)))/(1-(1+Q36)^(1/$M$6))+$E$20*((1-(1+Q36)^(-$J$23/$M$7)))/(1-(1+Q36)^(1/$M$7))+$E$21*((1-(1+Q36)^(-$J$24/$M$8)))/(1-(1+Q36)^(1/$M$8)) -> 0.067755448 | U36: =$E$4-$E$10-$E$11*(1+R36)^(-$E$5/$L$9)-$E$13*(1+R36)^(-$H$13/$L$9)-$E$14*(1+R36)^(-$H$14/$L$9) +$E$24*((1-(1+R36)^(-$E$5/$L$9)))/(1-(1+R36)^(1/$L$9))+$E$17*((1-(1+R36)^(-$J$20/$M$4)))/(1-(1+R36)^(1/$M$4))+$E$18*((1-(1+R36)^(-$J$21/$M$5)))/(1-(1+R36)^(1/$M$5))+$E$19*((1-(1+R36)^(-$J$22/$M$6)))/(1-(1+R36)^(1/$M$6))+$E$20*((1-(1+R36)^(-$J$23/$M$7)))/(1-(1+R36)^(1/$M$7))+$E$21*((1-(1+R36)^(-$J$24/$M$8)))/(1-(1+R36)^(1/$M$8)) -> -0.030565463
O37: 33 | P37: =IF(S36*U36>=0,R36,P36) -> 0.055531405 | Q37: =IF(T36*U36>=0,R36,Q36) -> 0.055531408 | R37: =(P37+Q37)/2 -> 0.055531407 | S37: =$E$4-$E$10-$E$11*(1+P37)^(-$E$5/$L$9)-$E$13*(1+P37)^(-$H$13/$L$9)-$E$14*(1+P37)^(-$H$14/$L$9) +$E$24*((1-(1+P37)^(-$E$5/$L$9)))/(1-(1+P37)^(1/$L$9))+$E$17*((1-(1+P37)^(-$J$20/$M$4)))/(1-(1+P37)^(1/$M$4))+$E$18*((1-(1+P37)^(-$J$21/$M$5)))/(1-(1+P37)^(1/$M$5))+$E$19*((1-(1+P37)^(-$J$22/$M$6)))/(1-(1+P37)^(1/$M$6))+$E$20*((1-(1+P37)^(-$J$23/$M$7)))/(1-(1+P37)^(1/$M$7))+$E$21*((1-(1+P37)^(-$J$24/$M$8)))/(1-(1+P37)^(1/$M$8)) -> -0.030565463 | T37: =$E$4-$E$10-$E$11*(1+Q37)^(-$E$5/$L$9)-$E$13*(1+Q37)^(-$H$13/$L$9)-$E$14*(1+Q37)^(-$H$14/$L$9) +$E$24*((1-(1+Q37)^(-$E$5/$L$9)))/(1-(1+Q37)^(1/$L$9))+$E$17*((1-(1+Q37)^(-$J$20/$M$4)))/(1-(1+Q37)^(1/$M$4))+$E$18*((1-(1+Q37)^(-$J$21/$M$5)))/(1-(1+Q37)^(1/$M$5))+$E$19*((1-(1+Q37)^(-$J$22/$M$6)))/(1-(1+Q37)^(1/$M$6))+$E$20*((1-(1+Q37)^(-$J$23/$M$7)))/(1-(1+Q37)^(1/$M$7))+$E$21*((1-(1+Q37)^(-$J$24/$M$8)))/(1-(1+Q37)^(1/$M$8)) -> 0.067755448 | U37: =$E$4-$E$10-$E$11*(1+R37)^(-$E$5/$L$9)-$E$13*(1+R37)^(-$H$13/$L$9)-$E$14*(1+R37)^(-$H$14/$L$9) +$E$24*((1-(1+R37)^(-$E$5/$L$9)))/(1-(1+R37)^(1/$L$9))+$E$17*((1-(1+R37)^(-$J$20/$M$4)))/(1-(1+R37)^(1/$M$4))+$E$18*((1-(1+R37)^(-$J$21/$M$5)))/(1-(1+R37)^(1/$M$5))+$E$19*((1-(1+R37)^(-$J$22/$M$6)))/(1-(1+R37)^(1/$M$6))+$E$20*((1-(1+R37)^(-$J$23/$M$7)))/(1-(1+R37)^(1/$M$7))+$E$21*((1-(1+R37)^(-$J$24/$M$8)))/(1-(1+R37)^(1/$M$8)) -> 0.018594894
O38: 34 | P38: =IF(S37*U37>=0,R37,P37) -> 0.055531405 | Q38: =IF(T37*U37>=0,R37,Q37) -> 0.055531407 | R38: =(P38+Q38)/2 -> 0.055531406 | S38: =$E$4-$E$10-$E$11*(1+P38)^(-$E$5/$L$9)-$E$13*(1+P38)^(-$H$13/$L$9)-$E$14*(1+P38)^(-$H$14/$L$9) +$E$24*((1-(1+P38)^(-$E$5/$L$9)))/(1-(1+P38)^(1/$L$9))+$E$17*((1-(1+P38)^(-$J$20/$M$4)))/(1-(1+P38)^(1/$M$4))+$E$18*((1-(1+P38)^(-$J$21/$M$5)))/(1-(1+P38)^(1/$M$5))+$E$19*((1-(1+P38)^(-$J$22/$M$6)))/(1-(1+P38)^(1/$M$6))+$E$20*((1-(1+P38)^(-$J$23/$M$7)))/(1-(1+P38)^(1/$M$7))+$E$21*((1-(1+P38)^(-$J$24/$M$8)))/(1-(1+P38)^(1/$M$8)) -> -0.030565463 | T38: =$E$4-$E$10-$E$11*(1+Q38)^(-$E$5/$L$9)-$E$13*(1+Q38)^(-$H$13/$L$9)-$E$14*(1+Q38)^(-$H$14/$L$9) +$E$24*((1-(1+Q38)^(-$E$5/$L$9)))/(1-(1+Q38)^(1/$L$9))+$E$17*((1-(1+Q38)^(-$J$20/$M$4)))/(1-(1+Q38)^(1/$M$4))+$E$18*((1-(1+Q38)^(-$J$21/$M$5)))/(1-(1+Q38)^(1/$M$5))+$E$19*((1-(1+Q38)^(-$J$22/$M$6)))/(1-(1+Q38)^(1/$M$6))+$E$20*((1-(1+Q38)^(-$J$23/$M$7)))/(1-(1+Q38)^(1/$M$7))+$E$21*((1-(1+Q38)^(-$J$24/$M$8)))/(1-(1+Q38)^(1/$M$8)) -> 0.018594894 | U38: =$E$4-$E$10-$E$11*(1+R38)^(-$E$5/$L$9)-$E$13*(1+R38)^(-$H$13/$L$9)-$E$14*(1+R38)^(-$H$14/$L$9) +$E$24*((1-(1+R38)^(-$E$5/$L$9)))/(1-(1+R38)^(1/$L$9))+$E$17*((1-(1+R38)^(-$J$20/$M$4)))/(1-(1+R38)^(1/$M$4))+$E$18*((1-(1+R38)^(-$J$21/$M$5)))/(1-(1+R38)^(1/$M$5))+$E$19*((1-(1+R38)^(-$J$22/$M$6)))/(1-(1+R38)^(1/$M$6))+$E$20*((1-(1+R38)^(-$J$23/$M$7)))/(1-(1+R38)^(1/$M$7))+$E$21*((1-(1+R38)^(-$J$24/$M$8)))/(1-(1+R38)^(1/$M$8)) -> -0.0059851868
O39: 35 | P39: =IF(S38*U38>=0,R38,P38) -> 0.055531406 | Q39: =IF(T38*U38>=0,R38,Q38) -> 0.055531407 | R39: =(P39+Q39)/2 -> 0.055531406 | S39: =$E$4-$E$10-$E$11*(1+P39)^(-$E$5/$L$9)-$E$13*(1+P39)^(-$H$13/$L$9)-$E$14*(1+P39)^(-$H$14/$L$9) +$E$24*((1-(1+P39)^(-$E$5/$L$9)))/(1-(1+P39)^(1/$L$9))+$E$17*((1-(1+P39)^(-$J$20/$M$4)))/(1-(1+P39)^(1/$M$4))+$E$18*((1-(1+P39)^(-$J$21/$M$5)))/(1-(1+P39)^(1/$M$5))+$E$19*((1-(1+P39)^(-$J$22/$M$6)))/(1-(1+P39)^(1/$M$6))+$E$20*((1-(1+P39)^(-$J$23/$M$7)))/(1-(1+P39)^(1/$M$7))+$E$21*((1-(1+P39)^(-$J$24/$M$8)))/(1-(1+P39)^(1/$M$8)) -> -0.0059851868 | T39: =$E$4-$E$10-$E$11*(1+Q39)^(-$E$5/$L$9)-$E$13*(1+Q39)^(-$H$13/$L$9)-$E$14*(1+Q39)^(-$H$14/$L$9) +$E$24*((1-(1+Q39)^(-$E$5/$L$9)))/(1-(1+Q39)^(1/$L$9))+$E$17*((1-(1+Q39)^(-$J$20/$M$4)))/(1-(1+Q39)^(1/$M$4))+$E$18*((1-(1+Q39)^(-$J$21/$M$5)))/(1-(1+Q39)^(1/$M$5))+$E$19*((1-(1+Q39)^(-$J$22/$M$6)))/(1-(1+Q39)^(1/$M$6))+$E$20*((1-(1+Q39)^(-$J$23/$M$7)))/(1-(1+Q39)^(1/$M$7))+$E$21*((1-(1+Q39)^(-$J$24/$M$8)))/(1-(1+Q39)^(1/$M$8)) -> 0.018594894 | U39: =$E$4-$E$10-$E$11*(1+R39)^(-$E$5/$L$9)-$E$13*(1+R39)^(-$H$13/$L$9)-$E$14*(1+R39)^(-$H$14/$L$9) +$E$24*((1-(1+R39)^(-$E$5/$L$9)))/(1-(1+R39)^(1/$L$9))+$E$17*((1-(1+R39)^(-$J$20/$M$4)))/(1-(1+R39)^(1/$M$4))+$E$18*((1-(1+R39)^(-$J$21/$M$5)))/(1-(1+R39)^(1/$M$5))+$E$19*((1-(1+R39)^(-$J$22/$M$6)))/(1-(1+R39)^(1/$M$6))+$E$20*((1-(1+R39)^(-$J$23/$M$7)))/(1-(1+R39)^(1/$M$7))+$E$21*((1-(1+R39)^(-$J$24/$M$8)))/(1-(1+R39)^(1/$M$8)) -> 0.0063048541
O40: 36 | P40: =IF(S39*U39>=0,R39,P39) -> 0.055531406 | Q40: =IF(T39*U39>=0,R39,Q39) -> 0.055531406 | R40: =(P40+Q40)/2 -> 0.055531406 | S40: =$E$4-$E$10-$E$11*(1+P40)^(-$E$5/$L$9)-$E$13*(1+P40)^(-$H$13/$L$9)-$E$14*(1+P40)^(-$H$14/$L$9) +$E$24*((1-(1+P40)^(-$E$5/$L$9)))/(1-(1+P40)^(1/$L$9))+$E$17*((1-(1+P40)^(-$J$20/$M$4)))/(1-(1+P40)^(1/$M$4))+$E$18*((1-(1+P40)^(-$J$21/$M$5)))/(1-(1+P40)^(1/$M$5))+$E$19*((1-(1+P40)^(-$J$22/$M$6)))/(1-(1+P40)^(1/$M$6))+$E$20*((1-(1+P40)^(-$J$23/$M$7)))/(1-(1+P40)^(1/$M$7))+$E$21*((1-(1+P40)^(-$J$24/$M$8)))/(1-(1+P40)^(1/$M$8)) -> -0.0059851868 | T40: =$E$4-$E$10-$E$11*(1+Q40)^(-$E$5/$L$9)-$E$13*(1+Q40)^(-$H$13/$L$9)-$E$14*(1+Q40)^(-$H$14/$L$9) +$E$24*((1-(1+Q40)^(-$E$5/$L$9)))/(1-(1+Q40)^(1/$L$9))+$E$17*((1-(1+Q40)^(-$J$20/$M$4)))/(1-(1+Q40)^(1/$M$4))+$E$18*((1-(1+Q40)^(-$J$21/$M$5)))/(1-(1+Q40)^(1/$M$5))+$E$19*((1-(1+Q40)^(-$J$22/$M$6)))/(1-(1+Q40)^(1/$M$6))+$E$20*((1-(1+Q40)^(-$J$23/$M$7)))/(1-(1+Q40)^(1/$M$7))+$E$21*((1-(1+Q40)^(-$J$24/$M$8)))/(1-(1+Q40)^(1/$M$8)) -> 0.0063048541 | U40: =$E$4-$E$10-$E$11*(1+R40)^(-$E$5/$L$9)-$E$13*(1+R40)^(-$H$13/$L$9)-$E$14*(1+R40)^(-$H$14/$L$9) +$E$24*((1-(1+R40)^(-$E$5/$L$9)))/(1-(1+R40)^(1/$L$9))+$E$17*((1-(1+R40)^(-$J$20/$M$4)))/(1-(1+R40)^(1/$M$4))+$E$18*((1-(1+R40)^(-$J$21/$M$5)))/(1-(1+R40)^(1/$M$5))+$E$19*((1-(1+R40)^(-$J$22/$M$6)))/(1-(1+R40)^(1/$M$6))+$E$20*((1-(1+R40)^(-$J$23/$M$7)))/(1-(1+R40)^(1/$M$7))+$E$21*((1-(1+R40)^(-$J$24/$M$8)))/(1-(1+R40)^(1/$M$8)) -> 0.00015973541
... O104: 100 | P104: =IF(S103*U103>=0,R103,P103) -> 0.055531406 | Q104: =IF(T103*U103>=0,R103,Q103) -> 0.055531406 | R104: =(P104+Q104)/2 -> 0.055531406 | S104: =$E$4-$E$10-$E$11*(1+P104)^(-$E$5/$L$9)-$E$13*(1+P104)^(-$H$13/$L$9)-$E$14*(1+P104)^(-$H$14/$L$9) +$E$24*((1-(1+P104)^(-$E$5/$L$9)))/(1-(1+P104)^(1/$L$9))+$E$17*((1-(1+P104)^(-$J$20/$M$4)))/(1-(1+P104)^(1/$M$4))+$E$18*((1-(1+P104)^(-$J$21/$M$5)))/(1-(1+P104)^(1/$M$5))+$E$19*((1-(1+P104)^(-$J$22/$M$6)))/(1-(1+P104)^(1/$M$6))+$E$20*((1-(1+P104)^(-$J$23/$M$7)))/(1-(1+P104)^(1/$M$7))+$E$21*((1-(1+P104)^(-$J$24/$M$8)))/(1-(1+P104)^(1/$M$8)) -> -1.3054978e-07 | T104: =$E$4-$E$10-$E$11*(1+Q104)^(-$E$5/$L$9)-$E$13*(1+Q104)^(-$H$13/$L$9)-$E$14*(1+Q104)^(-$H$14/$L$9) +$E$24*((1-(1+Q104)^(-$E$5/$L$9)))/(1-(1+Q104)^(1/$L$9))+$E$17*((1-(1+Q104)^(-$J$20/$M$4)))/(1-(1+Q104)^(1/$M$4))+$E$18*((1-(1+Q104)^(-$J$21/$M$5)))/(1-(1+Q104)^(1/$M$5))+$E$19*((1-(1+Q104)^(-$J$22/$M$6)))/(1-(1+Q104)^(1/$M$6))+$E$20*((1-(1+Q104)^(-$J$23/$M$7)))/(1-(1+Q104)^(1/$M$7))+$E$21*((1-(1+Q104)^(-$J$24/$M$8)))/(1-(1+Q104)^(1/$M$8)) -> 6.1310857e-08 | U104: =$E$4-$E$10-$E$11*(1+R104)^(-$E$5/$L$9)-$E$13*(1+R104)^(-$H$13/$L$9)-$E$14*(1+R104)^(-$H$14/$L$9) +$E$24*((1-(1+R104)^(-$E$5/$L$9)))/(1-(1+R104)^(1/$L$9))+$E$17*((1-(1+R104)^(-$J$20/$M$4)))/(1-(1+R104)^(1/$M$4))+$E$18*((1-(1+R104)^(-$J$21/$M$5)))/(1-(1+R104)^(1/$M$5))+$E$19*((1-(1+R104)^(-$J$22/$M$6)))/(1-(1+R104)^(1/$M$6))+$E$20*((1-(1+R104)^(-$J$23/$M$7)))/(1-(1+R104)^(1/$M$7))+$E$21*((1-(1+R104)^(-$J$24/$M$8)))/(1-(1+R104)^(1/$M$8)) -> 6.1310857e-08

Sheet Remaining debt
B2: Period | C2: Payment | D2: Principal | E2: Interest | F2: Remaining debt
A3: 0 | B3: =IF(A3<='APR and payment'!$E$5,'Remaining debt'!A3,"") -> 0 | F3: ='APR and payment'!E4 -> 4000000
A4: 1 | B4: =IF(A4<='APR and payment'!$E$5,'Remaining debt'!A4,"") -> 1 | C4: =IF(A4<='APR and payment'!$E$5,'APR and payment'!$E$24,"") -> 22461.232 | D4: =C4-E4 -> 4461.2317 | E4: =IF(A4<='APR and payment'!$E$5,F3*'APR and payment'!$E$6/'APR and payment'!$L$9,"") -> 18000 | F4: =IF(A4<='APR and payment'!$E$5,F3-D4,"") -> 3995538.8
A5: 2 | B5: =IF(A5<='APR and payment'!$E$5,'Remaining debt'!A5,"") -> 2 | C5: =IF(A5<='APR and payment'!$E$5,'APR and payment'!$E$24,"") -> 22461.232 | D5: =IF(A5<='APR and payment'!$E$5,C5-E5,"") -> 4481.3072 | E5: =IF(A5<='APR and payment'!$E$5,F4*'APR and payment'!$E$6/'APR and payment'!$L$9,"") -> 17979.924 | F5: =IF(A5<='APR and payment'!$E$5,F4-D5,"") -> 3991057.5
A6: 3 | B6: =IF(A6<='APR and payment'!$E$5,'Remaining debt'!A6,"") -> 3 | C6: =IF(A6<='APR and payment'!$E$5,'APR and payment'!$E$24,"") -> 22461.232 | D6: =IF(A6<='APR and payment'!$E$5,C6-E6,"") -> 4501.4731 | E6: =IF(A6<='APR and payment'!$E$5,F5*'APR and payment'!$E$6/'APR and payment'!$L$9,"") -> 17959.759 | F6: =IF(A6<='APR and payment'!$E$5,F5-D6,"") -> 3986556
A7: 4 | B7: =IF(A7<='APR and payment'!$E$5,'Remaining debt'!A7,"") -> 4 | C7: =IF(A7<='APR and payment'!$E$5,'APR and payment'!$E$24,"") -> 22461.232 | D7: =IF(A7<='APR and payment'!$E$5,C7-E7,"") -> 4521.7297 | E7: =IF(A7<='APR and payment'!$E$5,F6*'APR and payment'!$E$6/'APR and payment'!$L$9,"") -> 17939.502 | F7: =IF(A7<='APR and payment'!$E$5,F6-D7,"") -> 3982034.3
A8: 5 | B8: =IF(A8<='APR and payment'!$E$5,'Remaining debt'!A8,"") -> 5 | C8: =IF(A8<='APR and payment'!$E$5,'APR and payment'!$E$24,"") -> 22461.232 | D8: =IF(A8<='APR and payment'!$E$5,C8-E8,"") -> 4542.0775 | E8: =IF(A8<='APR and payment'!$E$5,F7*'APR and payment'!$E$6/'APR and payment'!$L$9,"") -> 17919.154 | F8: =IF(A8<='APR and payment'!$E$5,F7-D8,"") -> 3977492.2
A9: 6 | B9: =IF(A9<='APR and payment'!$E$5,'Remaining debt'!A9,"") -> 6 | C9: =IF(A9<='APR and payment'!$E$5,'APR and payment'!$E$24,"") -> 22461.232 | D9: =IF(A9<='APR and payment'!$E$5,C9-E9,"") -> 4562.5169 | E9: =IF(A9<='APR and payment'!$E$5,F8*'APR and payment'!$E$6/'APR and payment'!$L$9,"") -> 17898.715 | F9: =IF(A9<='APR and payment'!$E$5,F8-D9,"") -> 3972929.7
A10: 7 | B10: =IF(A10<='APR and payment'!$E$5,'Remaining debt'!A10,"") -> 7 | C10: =IF(A10<='APR and payment'!$E$5,'APR and payment'!$E$24,"") -> 22461.232 | D10: =IF(A10<='APR and payment'!$E$5,C10-E10,"") -> 4583.0482 | E10: =IF(A10<='APR and payment'!$E$5,F9*'APR and payment'!$E$6/'APR and payment'!$L$9,"") -> 17878.183 | F10: =IF(A10<='APR and payment'!$E$5,F9-D10,"") -> 3968346.6
A11: 8 | B11: =IF(A11<='APR and payment'!$E$5,'Remaining debt'!A11,"") -> 8 | C11: =IF(A11<='APR and payment'!$E$5,'APR and payment'!$E$24,"") -> 22461.232 | D11: =IF(A11<='APR and payment'!$E$5,C11-E11,"") -> 4603.6719 | E11: =IF(A11<='APR and payment'!$E$5,F10*'APR and payment'!$E$6/'APR and payment'!$L$9,"") -> 17857.56 | F11: =IF(A11<='APR and payment'!$E$5,F10-D11,"") -> 3963742.9
A12: 9 | B12: =IF(A12<='APR and payment'!$E$5,'Remaining debt'!A12,"") -> 9 | C12: =IF(A12<='APR and payment'!$E$5,'APR and payment'!$E$24,"") -> 22461.232 | D12: =IF(A12<='APR and payment'!$E$5,C12-E12,"") -> 4624.3884 | E12: =IF(A12<='APR and payment'!$E$5,F11*'APR and payment'!$E$6/'APR and payment'!$L$9,"") -> 17836.843 | F12: =IF(A12<='APR and payment'!$E$5,F11-D12,"") -> 3959118.6
